Workbook

Sheet HOW TO USE
B2: Copy paste the following data from your library into Raw_Data_Input

Sheet Raw_Data_Input
B2: Title | C2: Blank | D2: Favorite | E2: Length | F2: Artist | G2: Album | H2: Genre | I2: Plays | J2: Year
E3: 0
E4: 0
E5: 0
E6: 0
E7: 0
E8: 0
E9: 0
E10: 0
E11: 0
E12: 0
E13: 0
E14: 0
... E2092: 0

Sheet Summary Statistics
B2: Total Number of Songs | C2: Total Playtime (days) | D2: Total Plays | F2: Top 10 Artists | H2: =IF(C6=TRUE,"Playtime (hours)","Plays") -> Plays | J2: Top 10 Albums | L2: =IF(C7=TRUE,"Playtime (hours)","Plays") -> Plays
B3: ='Cleaned Data'!M3 -> 0 | C3: =SUM('Cleaned Data'!J3:J2000)/(60*24) -> 0 | D3: ='Cleaned Data'!N3 -> 0 | F3: 1 | G3: =IF(C6=TRUE,_xlfn.XLOOKUP(Calculations!B$3,Artists!$F$3:$F$1003,Artists!$B$3:$B$1003),_xlfn.XLOOKUP(Calculations!B$3,Artists!$E$3:$E$1003,Artists!$B$3:$B$1003)) -> 0 | H3: =IF(C6=TRUE,Calculations!B$3/60,Calculations!B$3) -> 0 | J3: 1 | K3: =IF(C7=TRUE,_xlfn.XLOOKUP(Calculations!M$3,Albums!$F$3:$F$1503,Albums!$B$3:$B$1503),_xlfn.XLOOKUP(Calculations!M$3,Albums!$E$3:$E$1503,Albums!$B$3:$B$1503)) -> 0 | L3: =IF(C7=TRUE,Calculations!M$3/60,Calculations!M$3) -> 0
F4: 2 | G4: =IF(C6=TRUE,_xlfn.XLOOKUP(Calculations!C$3,Artists!$F$3:$F$1003,Artists!$B$3:$B$1003),_xlfn.XLOOKUP(Calculations!C$3,Artists!$E$3:$E$1003,Artists!$B$3:$B$1003)) -> 0 | H4: =IF(C6=TRUE,Calculations!C$3/60,Calculations!C$3) -> 0 | J4: 2 | K4: =IF(C7=TRUE,_xlfn.XLOOKUP(Calculations!N$3,Albums!$F$3:$F$1503,Albums!$B$3:$B$1503),_xlfn.XLOOKUP(Calculations!N$3,Albums!$E$3:$E$1503,Albums!$B$3:$B$1503)) -> 0 | L4: =IF(C7=TRUE,Calculations!N$3/60,Calculations!N$3) -> 0
B5: Playtime (check) /Plays (no check) | F5: 3 | G5: =IF(C6=TRUE,_xlfn.XLOOKUP(Calculations!D$3,Artists!$F$3:$F$1003,Artists!$B$3:$B$1003),_xlfn.XLOOKUP(Calculations!D$3,Artists!$E$3:$E$1003,Artists!$B$3:$B$1003)) -> 0 | H5: =IF(C6=TRUE,Calculations!D$3/60,Calculations!D$3) -> 0 | J5: 3 | K5: =IF(C7=TRUE,_xlfn.XLOOKUP(Calculations!O$3,Albums!$F$3:$F$1503,Albums!$B$3:$B$1503),_xlfn.XLOOKUP(Calculations!O$3,Albums!$E$3:$E$1503,Albums!$B$3:$B$1503)) -> 0 | L5: =IF(C7=TRUE,Calculations!O$3/60,Calculations!O$3) -> 0
B6: Top 10 Artists | C6: FALSE | F6: 4 | G6: =IF(C6=TRUE,_xlfn.XLOOKUP(Calculations!E$3,Artists!$F$3:$F$1003,Artists!$B$3:$B$1003),_xlfn.XLOOKUP(Calculations!E$3,Artists!$E$3:$E$1003,Artists!$B$3:$B$1003)) -> 0 | H6: =IF(C6=TRUE,Calculations!E$3/60,Calculations!E$3) -> 0 | J6: 4 | K6: =IF(C7=TRUE,_xlfn.XLOOKUP(Calculations!P$3,Albums!$F$3:$F$1503,Albums!$B$3:$B$1503),_xlfn.XLOOKUP(Calculations!P$3,Albums!$E$3:$E$1503,Albums!$B$3:$B$1503)) -> 0 | L6: =IF(C7=TRUE,Calculations!P$3/60,Calculations!P$3) -> 0
B7: Top 10 Albums | C7: FALSE | F7: 5 | G7: =IF(C6=TRUE,_xlfn.XLOOKUP(Calculations!F$3,Artists!$F$3:$F$1003,Artists!$B$3:$B$1003),_xlfn.XLOOKUP(Calculations!F$3,Artists!$E$3:$E$1003,Artists!$B$3:$B$1003)) -> 0 | H7: =IF(C6=TRUE,Calculations!F$3/60,Calculations!F$3) -> 0 | J7: 5 | K7: =IF(C7=TRUE,_xlfn.XLOOKUP(Calculations!Q$3,Albums!$F$3:$F$1503,Albums!$B$3:$B$1503),_xlfn.XLOOKUP(Calculations!Q$3,Albums!$E$3:$E$1503,Albums!$B$3:$B$1503)) -> 0 | L7: =IF(C7=TRUE,Calculations!Q$3/60,Calculations!Q$3) -> 0
F8: 6 | G8: =IF(C6=TRUE,_xlfn.XLOOKUP(Calculations!G$3,Artists!$F$3:$F$1003,Artists!$B$3:$B$1003),_xlfn.XLOOKUP(Calculations!G$3,Artists!$E$3:$E$1003,Artists!$B$3:$B$1003)) -> 0 | H8: =IF(C6=TRUE,Calculations!G$3/60,Calculations!G$3) -> 0 | J8: 6 | K8: =IF(C7=TRUE,_xlfn.XLOOKUP(Calculations!R$3,Albums!$F$3:$F$1503,Albums!$B$3:$B$1503),_xlfn.XLOOKUP(Calculations!R$3,Albums!$E$3:$E$1503,Albums!$B$3:$B$1503)) -> 0 | L8: =IF(C7=TRUE,Calculations!R$3/60,Calculations!R$3) -> 0
F9: 7 | G9: =IF(C6=TRUE,_xlfn.XLOOKUP(Calculations!H$3,Artists!$F$3:$F$1003,Artists!$B$3:$B$1003),_xlfn.XLOOKUP(Calculations!H$3,Artists!$E$3:$E$1003,Artists!$B$3:$B$1003)) -> 0 | H9: =IF(C6=TRUE,Calculations!H$3/60,Calculations!H$3) -> 0 | J9: 7 | K9: =IF(C7=TRUE,_xlfn.XLOOKUP(Calculations!S$3,Albums!$F$3:$F$1503,Albums!$B$3:$B$1503),_xlfn.XLOOKUP(Calculations!S$3,Albums!$E$3:$E$1503,Albums!$B$3:$B$1503)) -> 0 | L9: =IF(C7=TRUE,Calculations!S$3/60,Calculations!S$3) -> 0
F10: 8 | G10: =IF(C6=TRUE,_xlfn.XLOOKUP(Calculations!I$3,Artists!$F$3:$F$1003,Artists!$B$3:$B$1003),_xlfn.XLOOKUP(Calculations!I$3,Artists!$E$3:$E$1003,Artists!$B$3:$B$1003)) -> 0 | H10: =IF(C6=TRUE,Calculations!I$3/60,Calculations!I$3) -> 0 | J10: 8 | K10: =IF(C7=TRUE,_xlfn.XLOOKUP(Calculations!T$3,Albums!$F$3:$F$1503,Albums!$B$3:$B$1503),_xlfn.XLOOKUP(Calculations!T$3,Albums!$E$3:$E$1503,Albums!$B$3:$B$1503)) -> 0 | L10: =IF(C7=TRUE,Calculations!T$3/60,Calculations!T$3) -> 0
F11: 9 | G11: =IF(C6=TRUE,_xlfn.XLOOKUP(Calculations!J$3,Artists!$F$3:$F$1003,Artists!$B$3:$B$1003),_xlfn.XLOOKUP(Calculations!J$3,Artists!$E$3:$E$1003,Artists!$B$3:$B$1003)) -> 0 | H11: =IF(C6=TRUE,Calculations!J$3/60,Calculations!J$3) -> 0 | J11: 9 | K11: =IF(C7=TRUE,_xlfn.XLOOKUP(Calculations!U$3,Albums!$F$3:$F$1503,Albums!$B$3:$B$1503),_xlfn.XLOOKUP(Calculations!U$3,Albums!$E$3:$E$1503,Albums!$B$3:$B$1503)) -> 0 | L11: =IF(C7=TRUE,Calculations!U$3/60,Calculations!U$3) -> 0
F12: 10 | G12: =IF(C6=TRUE,_xlfn.XLOOKUP(Calculations!K$3,Artists!$F$3:$F$1003,Artists!$B$3:$B$1003),_xlfn.XLOOKUP(Calculations!K$3,Artists!$E$3:$E$1003,Artists!$B$3:$B$1003)) -> 0 | H12: =IF(C6=TRUE,Calculations!K$3/60,Calculations!K$3) -> 0 | J12: 10 | K12: =IF(C7=TRUE,_xlfn.XLOOKUP(Calculations!V$3,Albums!$F$3:$F$1503,Albums!$B$3:$B$1503),_xlfn.XLOOKUP(Calculations!V$3,Albums!$E$3:$E$1503,Albums!$B$3:$B$1503)) -> 0 | L12: =IF(C7=TRUE,Calculations!V$3/60,Calculations!V$3) -> 0

Sheet Graphs

Sheet Artists
B2: Artist | C2: Total Songs | D2: Runtime (minutes) | E2: Plays | F2: Playtime (minutes)
C3: =IF(B3>0,COUNTIF('Cleaned Data'!C$4:C$5004,Artists!B3),"N/A") -> N/A | D3: =IF(B3>0,SUMIF('Cleaned Data'!C$4:C$5004,Artists!B3,'Cleaned Data'!I$4:I$5004),"N/A") -> N/A | E3: =IF(B3>0,SUMIF('Cleaned Data'!C$4:C$5004,Artists!B3,'Cleaned Data'!H$4:H$5004),0) -> 0 | F3: =IF(B3>0,SUMIF('Cleaned Data'!C$4:C$5004,B3,'Cleaned Data'!J$4:J$5004),0) -> 0
C4: =IF(B4>0,COUNTIF('Cleaned Data'!C$4:C$5004,Artists!B4),"N/A") -> N/A | D4: =IF(B4>0,SUMIF('Cleaned Data'!C$4:C$5004,Artists!B4,'Cleaned Data'!I$4:I$5004),"N/A") -> N/A | E4: =IF(B4>0,SUMIF('Cleaned Data'!C$4:C$5004,Artists!B4,'Cleaned Data'!H$4:H$5004),0) -> 0 | F4: =IF(B4>0,SUMIF('Cleaned Data'!C$4:C$5004,B4,'Cleaned Data'!J$4:J$5004),0) -> 0
C5: =IF(B5>0,COUNTIF('Cleaned Data'!C$4:C$5004,Artists!B5),"N/A") -> N/A | D5: =IF(B5>0,SUMIF('Cleaned Data'!C$4:C$5004,Artists!B5,'Cleaned Data'!I$4:I$5004),"N/A") -> N/A | E5: =IF(B5>0,SUMIF('Cleaned Data'!C$4:C$5004,Artists!B5,'Cleaned Data'!H$4:H$5004),0) -> 0 | F5: =IF(B5>0,SUMIF('Cleaned Data'!C$4:C$5004,B5,'Cleaned Data'!J$4:J$5004),0) -> 0
C6: =IF(B6>0,COUNTIF('Cleaned Data'!C$4:C$5004,Artists!B6),"N/A") -> N/A | D6: =IF(B6>0,SUMIF('Cleaned Data'!C$4:C$5004,Artists!B6,'Cleaned Data'!I$4:I$5004),"N/A") -> N/A | E6: =IF(B6>0,SUMIF('Cleaned Data'!C$4:C$5004,Artists!B6,'Cleaned Data'!H$4:H$5004),0) -> 0 | F6: =IF(B6>0,SUMIF('Cleaned Data'!C$4:C$5004,B6,'Cleaned Data'!J$4:J$5004),0) -> 0
C7: =IF(B7>0,COUNTIF('Cleaned Data'!C$4:C$5004,Artists!B7),"N/A") -> N/A | D7: =IF(B7>0,SUMIF('Cleaned Data'!C$4:C$5004,Artists!B7,'Cleaned Data'!I$4:I$5004),"N/A") -> N/A | E7: =IF(B7>0,SUMIF('Cleaned Data'!C$4:C$5004,Artists!B7,'Cleaned Data'!H$4:H$5004),0) -> 0 | F7: =IF(B7>0,SUMIF('Cleaned Data'!C$4:C$5004,B7,'Cleaned Data'!J$4:J$5004),0) -> 0
C8: =IF(B8>0,COUNTIF('Cleaned Data'!C$4:C$5004,Artists!B8),"N/A") -> N/A | D8: =IF(B8>0,SUMIF('Cleaned Data'!C$4:C$5004,Artists!B8,'Cleaned Data'!I$4:I$5004),"N/A") -> N/A | E8: =IF(B8>0,SUMIF('Cleaned Data'!C$4:C$5004,Artists!B8,'Cleaned Data'!H$4:H$5004),0) -> 0 | F8: =IF(B8>0,SUMIF('Cleaned Data'!C$4:C$5004,B8,'Cleaned Data'!J$4:J$5004),0) -> 0
C9: =IF(B9>0,COUNTIF('Cleaned Data'!C$4:C$5004,Artists!B9),"N/A") -> N/A | D9: =IF(B9>0,SUMIF('Cleaned Data'!C$4:C$5004,Artists!B9,'Cleaned Data'!I$4:I$5004),"N/A") -> N/A | E9: =IF(B9>0,SUMIF('Cleaned Data'!C$4:C$5004,Artists!B9,'Cleaned Data'!H$4:H$5004),0) -> 0 | F9: =IF(B9>0,SUMIF('Cleaned Data'!C$4:C$5004,B9,'Cleaned Data'!J$4:J$5004),0) -> 0
C10: =IF(B10>0,COUNTIF('Cleaned Data'!C$4:C$5004,Artists!B10),"N/A") -> N/A | D10: =IF(B10>0,SUMIF('Cleaned Data'!C$4:C$5004,Artists!B10,'Cleaned Data'!I$4:I$5004),"N/A") -> N/A | E10: =IF(B10>0,SUMIF('Cleaned Data'!C$4:C$5004,Artists!B10,'Cleaned Data'!H$4:H$5004),0) -> 0 | F10: =IF(B10>0,SUMIF('Cleaned Data'!C$4:C$5004,B10,'Cleaned Data'!J$4:J$5004),0) -> 0
C11: =IF(B11>0,COUNTIF('Cleaned Data'!C$4:C$5004,Artists!B11),"N/A") -> N/A | D11: =IF(B11>0,SUMIF('Cleaned Data'!C$4:C$5004,Artists!B11,'Cleaned Data'!I$4:I$5004),"N/A") -> N/A | E11: =IF(B11>0,SUMIF('Cleaned Data'!C$4:C$5004,Artists!B11,'Cleaned Data'!H$4:H$5004),0) -> 0 | F11: =IF(B11>0,SUMIF('Cleaned Data'!C$4:C$5004,B11,'Cleaned Data'!J$4:J$5004),0) -> 0
C12: =IF(B12>0,COUNTIF('Cleaned Data'!C$4:C$5004,Artists!B12),"N/A") -> N/A | D12: =IF(B12>0,SUMIF('Cleaned Data'!C$4:C$5004,Artists!B12,'Cleaned Data'!I$4:I$5004),"N/A") -> N/A | E12: =IF(B12>0,SUMIF('Cleaned Data'!C$4:C$5004,Artists!B12,'Cleaned Data'!H$4:H$5004),0) -> 0 | F12: =IF(B12>0,SUMIF('Cleaned Data'!C$4:C$5004,B12,'Cleaned Data'!J$4:J$5004),0) -> 0
C13: =IF(B13>0,COUNTIF('Cleaned Data'!C$4:C$5004,Artists!B13),"N/A") -> N/A | D13: =IF(B13>0,SUMIF('Cleaned Data'!C$4:C$5004,Artists!B13,'Cleaned Data'!I$4:I$5004),"N/A") -> N/A | E13: =IF(B13>0,SUMIF('Cleaned Data'!C$4:C$5004,Artists!B13,'Cleaned Data'!H$4:H$5004),0) -> 0 | F13: =IF(B13>0,SUMIF('Cleaned Data'!C$4:C$5004,B13,'Cleaned Data'!J$4:J$5004),0) -> 0
C14: =IF(B14>0,COUNTIF('Cleaned Data'!C$4:C$5004,Artists!B14),"N/A") -> N/A | D14: =IF(B14>0,SUMIF('Cleaned Data'!C$4:C$5004,Artists!B14,'Cleaned Data'!I$4:I$5004),"N/A") -> N/A | E14: =IF(B14>0,SUMIF('Cleaned Data'!C$4:C$5004,Artists!B14,'Cleaned Data'!H$4:H$5004),0) -> 0 | F14: =IF(B14>0,SUMIF('Cleaned Data'!C$4:C$5004,B14,'Cleaned Data'!J$4:J$5004),0) -> 0
... C1003: =IF(B1003>0,COUNTIF('Cleaned Data'!C$4:C$5004,Artists!B1003),"N/A") -> N/A | D1003: =IF(B1003>0,SUMIF('Cleaned Data'!C$4:C$5004,Artists!B1003,'Cleaned Data'!I$4:I$5004),"N/A") -> N/A | E1003: =IF(B1003>0,SUMIF('Cleaned Data'!C$4:C$5004,Artists!B1003,'Cleaned Data'!H$4:H$5004),0) -> 0 | F1003: =IF(B1003>0,SUMIF('Cleaned Data'!C$4:C$5004,B1003,'Cleaned Data'!J$4:J$5004),0) -> 0

Sheet Albums
B2: Album | C2: Total Songs | D2: Runtime (minutes) | E2: Plays | F2: Playtime
C3: =IF(B3>0,COUNTIF('Cleaned Data'!D$4:D$5004,B3),0) -> 0 | D3: =IF(B3>0,SUMIF('Cleaned Data'!D$4:D$5000,B3,'Cleaned Data'!I$4:I$5004),"N/A") -> N/A | E3: =IF(B3>0,SUMIF('Cleaned Data'!D$4:D$5004,B3,'Cleaned Data'!H$4:H$5004),0) -> 0 | F3: =IF(B3>0,SUMIF('Cleaned Data'!D$4:D$5004,B3,'Cleaned Data'!J$4:J$5004),0) -> 0
C4: =IF(B4>0,COUNTIF('Cleaned Data'!D$4:D$5004,B4),0) -> 0 | D4: =IF(B4>0,SUMIF('Cleaned Data'!D$4:D$5000,B4,'Cleaned Data'!I$4:I$5004),"N/A") -> N/A | E4: =IF(B4>0,SUMIF('Cleaned Data'!D$4:D$5004,B4,'Cleaned Data'!H$4:H$5004),0) -> 0 | F4: =IF(B4>0,SUMIF('Cleaned Data'!D$4:D$5004,B4,'Cleaned Data'!J$4:J$5004),0) -> 0
C5: =IF(B5>0,COUNTIF('Cleaned Data'!D$4:D$5004,B5),0) -> 0 | D5: =IF(B5>0,SUMIF('Cleaned Data'!D$4:D$5000,B5,'Cleaned Data'!I$4:I$5004),"N/A") -> N/A | E5: =IF(B5>0,SUMIF('Cleaned Data'!D$4:D$5004,B5,'Cleaned Data'!H$4:H$5004),0) -> 0 | F5: =IF(B5>0,SUMIF('Cleaned Data'!D$4:D$5004,B5,'Cleaned Data'!J$4:J$5004),0) -> 0
C6: =IF(B6>0,COUNTIF('Cleaned Data'!D$4:D$5004,B6),0) -> 0 | D6: =IF(B6>0,SUMIF('Cleaned Data'!D$4:D$5000,B6,'Cleaned Data'!I$4:I$5004),"N/A") -> N/A | E6: =IF(B6>0,SUMIF('Cleaned Data'!D$4:D$5004,B6,'Cleaned Data'!H$4:H$5004),0) -> 0 | F6: =IF(B6>0,SUMIF('Cleaned Data'!D$4:D$5004,B6,'Cleaned Data'!J$4:J$5004),0) -> 0
C7: =IF(B7>0,COUNTIF('Cleaned Data'!D$4:D$5004,B7),0) -> 0 | D7: =IF(B7>0,SUMIF('Cleaned Data'!D$4:D$5000,B7,'Cleaned Data'!I$4:I$5004),"N/A") -> N/A | E7: =IF(B7>0,SUMIF('Cleaned Data'!D$4:D$5004,B7,'Cleaned Data'!H$4:H$5004),0) -> 0 | F7: =IF(B7>0,SUMIF('Cleaned Data'!D$4:D$5004,B7,'Cleaned Data'!J$4:J$5004),0) -> 0
C8: =IF(B8>0,COUNTIF('Cleaned Data'!D$4:D$5004,B8),0) -> 0 | D8: =IF(B8>0,SUMIF('Cleaned Data'!D$4:D$5000,B8,'Cleaned Data'!I$4:I$5004),"N/A") -> N/A | E8: =IF(B8>0,SUMIF('Cleaned Data'!D$4:D$5004,B8,'Cleaned Data'!H$4:H$5004),0) -> 0 | F8: =IF(B8>0,SUMIF('Cleaned Data'!D$4:D$5004,B8,'Cleaned Data'!J$4:J$5004),0) -> 0
C9: =IF(B9>0,COUNTIF('Cleaned Data'!D$4:D$5004,B9),0) -> 0 | D9: =IF(B9>0,SUMIF('Cleaned Data'!D$4:D$5000,B9,'Cleaned Data'!I$4:I$5004),"N/A") -> N/A | E9: =IF(B9>0,SUMIF('Cleaned Data'!D$4:D$5004,B9,'Cleaned Data'!H$4:H$5004),0) -> 0 | F9: =IF(B9>0,SUMIF('Cleaned Data'!D$4:D$5004,B9,'Cleaned Data'!J$4:J$5004),0) -> 0
C10: =IF(B10>0,COUNTIF('Cleaned Data'!D$4:D$5004,B10),0) -> 0 | D10: =IF(B10>0,SUMIF('Cleaned Data'!D$4:D$5000,B10,'Cleaned Data'!I$4:I$5004),"N/A") -> N/A | E10: =IF(B10>0,SUMIF('Cleaned Data'!D$4:D$5004,B10,'Cleaned Data'!H$4:H$5004),0) -> 0 | F10: =IF(B10>0,SUMIF('Cleaned Data'!D$4:D$5004,B10,'Cleaned Data'!J$4:J$5004),0) -> 0
C11: =IF(B11>0,COUNTIF('Cleaned Data'!D$4:D$5004,B11),0) -> 0 | D11: =IF(B11>0,SUMIF('Cleaned Data'!D$4:D$5000,B11,'Cleaned Data'!I$4:I$5004),"N/A") -> N/A | E11: =IF(B11>0,SUMIF('Cleaned Data'!D$4:D$5004,B11,'Cleaned Data'!H$4:H$5004),0) -> 0 | F11: =IF(B11>0,SUMIF('Cleaned Data'!D$4:D$5004,B11,'Cleaned Data'!J$4:J$5004),0) -> 0
C12: =IF(B12>0,COUNTIF('Cleaned Data'!D$4:D$5004,B12),0) -> 0 | D12: =IF(B12>0,SUMIF('Cleaned Data'!D$4:D$5000,B12,'Cleaned Data'!I$4:I$5004),"N/A") -> N/A | E12: =IF(B12>0,SUMIF('Cleaned Data'!D$4:D$5004,B12,'Cleaned Data'!H$4:H$5004),0) -> 0 | F12: =IF(B12>0,SUMIF('Cleaned Data'!D$4:D$5004,B12,'Cleaned Data'!J$4:J$5004),0) -> 0
C13: =IF(B13>0,COUNTIF('Cleaned Data'!D$4:D$5004,B13),0) -> 0 | D13: =IF(B13>0,SUMIF('Cleaned Data'!D$4:D$5000,B13,'Cleaned Data'!I$4:I$5004),"N/A") -> N/A | E13: =IF(B13>0,SUMIF('Cleaned Data'!D$4:D$5004,B13,'Cleaned Data'!H$4:H$5004),0) -> 0 | F13: =IF(B13>0,SUMIF('Cleaned Data'!D$4:D$5004,B13,'Cleaned Data'!J$4:J$5004),0) -> 0
C14: =IF(B14>0,COUNTIF('Cleaned Data'!D$4:D$5004,B14),0) -> 0 | D14: =IF(B14>0,SUMIF('Cleaned Data'!D$4:D$5000,B14,'Cleaned Data'!I$4:I$5004),"N/A") -> N/A | E14: =IF(B14>0,SUMIF('Cleaned Data'!D$4:D$5004,B14,'Cleaned Data'!H$4:H$5004),0) -> 0 | F14: =IF(B14>0,SUMIF('Cleaned Data'!D$4:D$5004,B14,'Cleaned Data'!J$4:J$5004),0) -> 0
... C1500: =IF(B1500>0,COUNTIF('Cleaned Data'!D$4:D$5004,B1500),0) -> 0 | D1500: =IF(B1500>0,SUMIF('Cleaned Data'!D$4:D$5000,B1500,'Cleaned Data'!I$4:I$5004),"N/A") -> N/A | E1500: =IF(B1500>0,SUMIF('Cleaned Data'!D$4:D$5004,B1500,'Cleaned Data'!H$4:H$5004),0) -> 0 | F1500: =IF(B1500>0,SUMIF('Cleaned Data'!D$4:D$5004,B1500,'Cleaned Data'!J$4:J$5004),0) -> 0

Sheet Calculations
B2: Top 10 Artists | M2: Top 10 Albums | X2: Years | Y2: # of Songs | Z2: Playtime | AA2: Plays | AC2: Decade Data | AJ2: =AE4 -> 1900s | AM2: =AE5 -> 1910s | AP2: =AE6 -> 1920s | AS2: =$AE7 -> 1930s | AV2: =$AE8 -> 1940s | AY2: =$AE9 -> 1950s | BB2: =$AE10 -> 1960s | BE2: =$AE11 -> 1970s | BH2: =$AE12 -> 1980s | BK2: =$AE13 -> 1990s | BN2: =$AE14 -> 2000s | BQ2: =$AE15 -> 2010s | BT2: =$AE16 -> 2020s | BW2: =$AE17 -> 2030s | BZ2: =$AE18 -> 2040s
B3: =IF('Summary Statistics'!C6=TRUE,MAX(Artists!F3:F1003),MAX(Artists!E3:E1003)) -> 0 | C3: =IF('Summary Statistics'!$C$6=TRUE,_xlfn.MAXIFS(Artists!$F3:'Artists'!$F1003,B$4:B$1004,TRUE),_xlfn.MAXIFS(Artists!$E3:'Artists'!$E1003,B$4:B$1004,TRUE)) -> 0 | D3: =IF('Summary Statistics'!$C$6=TRUE,_xlfn.MAXIFS(Artists!$F3:'Artists'!$F1003,C$4:C$1004,TRUE),_xlfn.MAXIFS(Artists!$E3:'Artists'!$E1003,C$4:C$1004,TRUE)) -> 0 | E3: =IF('Summary Statistics'!$C$6=TRUE,_xlfn.MAXIFS(Artists!$F3:'Artists'!$F1003,D$4:D$1004,TRUE),_xlfn.MAXIFS(Artists!$E3:'Artists'!$E1003,D$4:D$1004,TRUE)) -> 0 | F3: =IF('Summary Statistics'!$C$6=TRUE,_xlfn.MAXIFS(Artists!$F3:'Artists'!$F1003,E$4:E$1004,TRUE),_xlfn.MAXIFS(Artists!$E3:'Artists'!$E1003,E$4:E$1004,TRUE)) -> 0 | G3: =IF('Summary Statistics'!$C$6=TRUE,_xlfn.MAXIFS(Artists!$F3:'Artists'!$F1003,F$4:F$1004,TRUE),_xlfn.MAXIFS(Artists!$E3:'Artists'!$E1003,F$4:F$1004,TRUE)) -> 0 | H3: =IF('Summary Statistics'!$C$6=TRUE,_xlfn.MAXIFS(Artists!$F3:'Artists'!$F1003,G$4:G$1004,TRUE),_xlfn.MAXIFS(Artists!$E3:'Artists'!$E1003,G$4:G$1004,TRUE)) -> 0 | I3: =IF('Summary Statistics'!$C$6=TRUE,_xlfn.MAXIFS(Artists!$F3:'Artists'!$F1003,H$4:H$1004,TRUE),_xlfn.MAXIFS(Artists!$E3:'Artists'!$E1003,H$4:H$1004,TRUE)) -> 0 | J3: =IF('Summary Statistics'!$C$6=TRUE,_xlfn.MAXIFS(Artists!$F3:'Artists'!$F1003,I$4:I$1004,TRUE),_xlfn.MAXIFS(Artists!$E3:'Artists'!$E1003,I$4:I$1004,TRUE)) -> 0 | K3: =IF('Summary Statistics'!$C$6=TRUE,_xlfn.MAXIFS(Artists!$F3:'Artists'!$F1003,J$4:J$1004,TRUE),_xlfn.MAXIFS(Artists!$E3:'Artists'!$E1003,J$4:J$1004,TRUE)) -> 0 | M3: =IF('Summary Statistics'!C7=TRUE,MAX(Albums!F3:F1503),MAX(Albums!E3:E1503)) -> 0 | N3: =IF('Summary Statistics'!$C$7=TRUE,_xlfn.MAXIFS(Albums!$F3:'Albums'!$F1503,M$4:M$1504,TRUE),_xlfn.MAXIFS(Albums!$E3:'Albums'!$E1503,M$4:M$1504,TRUE)) -> 0 | O3: =IF('Summary Statistics'!$C$7=TRUE,_xlfn.MAXIFS(Albums!$F3:'Albums'!$F1503,N$4:N$1504,TRUE),_xlfn.MAXIFS(Albums!$E3:'Albums'!$E1503,N$4:N$1504,TRUE)) -> 0 | P3: =IF('Summary Statistics'!$C$7=TRUE,_xlfn.MAXIFS(Albums!$F3:'Albums'!$F1503,O$4:O$1504,TRUE),_xlfn.MAXIFS(Albums!$E3:'Albums'!$E1503,O$4:O$1504,TRUE)) -> 0 | Q3: =IF('Summary Statistics'!$C$7=TRUE,_xlfn.MAXIFS(Albums!$F3:'Albums'!$F1503,P$4:P$1504,TRUE),_xlfn.MAXIFS(Albums!$E3:'Albums'!$E1503,P$4:P$1504,TRUE)) -> 0 | R3: =IF('Summary Statistics'!$C$7=TRUE,_xlfn.MAXIFS(Albums!$F3:'Albums'!$F1503,Q$4:Q$1504,TRUE),_xlfn.MAXIFS(Albums!$E3:'Albums'!$E1503,Q$4:Q$1504,TRUE)) -> 0 | S3: =IF('Summary Statistics'!$C$7=TRUE,_xlfn.MAXIFS(Albums!$F3:'Albums'!$F1503,R$4:R$1504,TRUE),_xlfn.MAXIFS(Albums!$E3:'Albums'!$E1503,R$4:R$1504,TRUE)) -> 0 | T3: =IF('Summary Statistics'!$C$7=TRUE,_xlfn.MAXIFS(Albums!$F3:'Albums'!$F1503,S$4:S$1504,TRUE),_xlfn.MAXIFS(Albums!$E3:'Albums'!$E1503,S$4:S$1504,TRUE)) -> 0 | U3: =IF('Summary Statistics'!$C$7=TRUE,_xlfn.MAXIFS(Albums!$F3:'Albums'!$F1503,T$4:T$1504,TRUE),_xlfn.MAXIFS(Albums!$E3:'Albums'!$E1503,T$4:T$1504,TRUE)) -> 0 | V3: =IF('Summary Statistics'!$C$7=TRUE,_xlfn.MAXIFS(Albums!$F3:'Albums'!$F1503,U$4:U$1504,TRUE),_xlfn.MAXIFS(Albums!$E3:'Albums'!$E1503,U$4:U$1504,TRUE)) -> 0 | X3: =1900 -> 1900 | Y3: =COUNTIF('Cleaned Data'!$K$4:$K$5004,X3) -> 0 | Z3: =SUMIF('Cleaned Data'!$K$4:'Cleaned Data'!$K$5004,Calculations!X3,'Cleaned Data'!$J$4:$J$5004) -> 0 | AA3: =SUMIF('Cleaned Data'!$K$4:'Cleaned Data'!$K$5004,Calculations!X3,'Cleaned Data'!$H$4:$H$5004) -> 0 | AC3: Decade Start | AD3: Decade End | AE3: Decade Title | AF3: # of Songs | AG3: Playtime (days) | AH3: Plays | AJ3: =IF(AND($AC$4<=$X3,$X3<$AD$4),Y3,0) -> 0 | AK3: =IF(AND($AC$4<=$X3,$X3<$AD$4),Z3,0) -> 0 | AL3: =IF(AND($AC$4<=$X3,$X3<$AD$4),AA3,0) -> 0 | AM3: =IF(AND($AC$5<=$X3,$X3<$AD$5),Y3,0) -> 0 | AN3: =IF(AND($AC$5<=$X3,$X3<$AD$5),Z3,0) -> 0 | AO3: =IF(AND($AC$5<=$X3,$X3<$AD$5),AA3,0) -> 0 | AP3: =IF(AND($AC$6<=$X3,$X3<$AD$6),Y3,0) -> 0 | AQ3: =IF(AND($AC$6<=$X3,$X3<$AD$6),Z3,0) -> 0 | AR3: =IF(AND($AC$6<=$X3,$X3<$AD$6),AA3,0) -> 0 | AS3: =IF(AND($AC$7<=$X3,$X3<$AD$7),Y3,0) -> 0 | AT3: =IF(AND($AC$7<=$X3,$X3<$AD$7),Z3,0) -> 0 | AU3: =IF(AND($AC$7<=$X3,$X3<$AD$7),AA3,0) -> 0 | AV3: =IF(AND($AC$8<=$X3,$X3<$AD$8),Y3,0) -> 0 | AW3: =IF(AND($AC$8<=$X3,$X3<$AD$8),Z3,0) -> 0 | AX3: =IF(AND($AC$8<=$X3,$X3<$AD$8),AA3,0) -> 0 | AY3: =IF(AND($AC$9<=$X3,$X3<$AD$9),Y3,0) -> 0 | AZ3: =IF(AND($AC$9<=$X3,$X3<$AD$9),Z3,0) -> 0 | BA3: =IF(AND($AC$9<=$X3,$X3<$AD$9),AA3,0) -> 0 | BB3: =IF(AND($AC$10<=$X3,$X3<$AD$10),Y3,0) -> 0 | BC3: =IF(AND($AC$10<=$X3,$X3<$AD$10),Z3,0) -> 0 | BD3: =IF(AND($AC$10<=$X3,$X3<$AD$10),AA3,0) -> 0 | BE3: =IF(AND($AC$11<=$X3,$X3<$AD$11),Y3,0) -> 0 | BF3: =IF(AND($AC$11<=$X3,$X3<$AD$11),Z3,0) -> 0 | BG3: =IF(AND($AC$11<=$X3,$X3<$AD$11),AA3,0) -> 0 | BH3: =IF(AND($AC$12<=$X3,$X3<$AD$12),Y3,0) -> 0 | BI3: =IF(AND($AC$12<=$X3,$X3<$AD$12),Z3,0) -> 0 | BJ3: =IF(AND($AC$12<=$X3,$X3<$AD$12),AA3,0) -> 0 | BK3: =IF(AND($AC$13<=$X3,$X3<$AD$13),Y3,0) -> 0 | BL3: =IF(AND($AC$13<=$X3,$X3<$AD$13),Z3,0) -> 0 | BM3: =IF(AND($AC$13<=$X3,$X3<$AD$13),AA3,0) -> 0 | BN3: =IF(AND($AC$14<=$X3,$X3<$AD$14),Y3,0) -> 0 | BO3: =IF(AND($AC$14<=$X3,$X3<$AD$14),Z3,0) -> 0 | BP3: =IF(AND($AC$14<=$X3,$X3<$AD$14),AA3,0) -> 0 | BQ3: =IF(AND($AC$15<=$X3,$X3<$AD$15),Y3,0) -> 0 | BR3: =IF(AND($AC$15<=$X3,$X3<$AD$15),Z3,0) -> 0 | BS3: =IF(AND($AC$15<=$X3,$X3<$AD$15),AA3,0) -> 0 | BT3: =IF(AND($AC$16<=$X3,$X3<$AD$16),Y3,0) -> 0 | BU3: =IF(AND($AC$16<=$X3,$X3<$AD$16),Z3,0) -> 0 | BV3: =IF(AND($AC$16<=$X3,$X3<$AD$16),AA3,0) -> 0 | BW3: =IF(AND($AC$17<=$X3,$X3<$AD$17),Y3,0) -> 0 | BX3: =IF(AND($AC$17<=$X3,$X3<$AD$17),Z3,0) -> 0 | BY3: =IF(AND($AC$17<=$X3,$X3<$AD$17),AA3,0) -> 0 | BZ3: =IF(AND($AC$18<=$X3,$X3<$AD$18),Y3,0) -> 0 | CA3: =IF(AND($AC$18<=$X3,$X3<$AD$18),Z3,0) -> 0 | CB3: =IF(AND($AC$18<=$X3,$X3<$AD$18),AA3,0) -> 0
B4: =IF('Summary Statistics'!$C$6=TRUE,Artists!$F3<B$3,Artists!$E3<B$3) -> FALSE | C4: =IF('Summary Statistics'!$C$6=TRUE,Artists!$F3<C$3,Artists!$E3<C$3) -> FALSE | D4: =IF('Summary Statistics'!$C$6=TRUE,Artists!$F3<D$3,Artists!$E3<D$3) -> FALSE | E4: =IF('Summary Statistics'!$C$6=TRUE,Artists!$F3<E$3,Artists!$E3<E$3) -> FALSE | F4: =IF('Summary Statistics'!$C$6=TRUE,Artists!$F3<F$3,Artists!$E3<F$3) -> FALSE | G4: =IF('Summary Statistics'!$C$6=TRUE,Artists!$F3<G$3,Artists!$E3<G$3) -> FALSE | H4: =IF('Summary Statistics'!$C$6=TRUE,Artists!$F3<H$3,Artists!$E3<H$3) -> FALSE | I4: =IF('Summary Statistics'!$C$6=TRUE,Artists!$F3<I$3,Artists!$E3<I$3) -> FALSE | ... K4: =IF('Summary Statistics'!$C$6=TRUE,Artists!$F3<K$3,Artists!$E3<K$3) -> FALSE | M4: =IF('Summary Statistics'!$C$7=TRUE,Albums!$F3<M$3,Albums!$E3<M$3) -> FALSE | N4: =IF('Summary Statistics'!$C$7=TRUE,Albums!$F3<N$3,Albums!$E3<N$3) -> FALSE | O4: =IF('Summary Statistics'!$C$7=TRUE,Albums!$F3<O$3,Albums!$E3<O$3) -> FALSE | P4: =IF('Summary Statistics'!$C$7=TRUE,Albums!$F3<P$3,Albums!$E3<P$3) -> FALSE | Q4: =IF('Summary Statistics'!$C$7=TRUE,Albums!$F3<Q$3,Albums!$E3<Q$3) -> FALSE | R4: =IF('Summary Statistics'!$C$7=TRUE,Albums!$F3<R$3,Albums!$E3<R$3) -> FALSE | S4: =IF('Summary Statistics'!$C$7=TRUE,Albums!$F3<S$3,Albums!$E3<S$3) -> FALSE | T4: =IF('Summary Statistics'!$C$7=TRUE,Albums!$F3<T$3,Albums!$E3<T$3) -> FALSE | ... V4: =IF('Summary Statistics'!$C$7=TRUE,Albums!$F3<V$3,Albums!$E3<V$3) -> FALSE | X4: =1+X3 -> 1901 | Y4: =COUNTIF('Cleaned Data'!$K$4:$K$5004,X4) -> 0 | Z4: =SUMIF('Cleaned Data'!$K$4:'Cleaned Data'!$K$5004,Calculations!X4,'Cleaned Data'!$J$4:$J$5004) -> 0 | AA4: =SUMIF('Cleaned Data'!$K$4:'Cleaned Data'!$K$5004,Calculations!X4,'Cleaned Data'!$H$4:$H$5004) -> 0 | AC4: 1900 | AD4: 1910 | AE4: 1900s | AF4: =SUM(AJ3:AJ153) -> 0 | AG4: =SUM(AK3:AK153) -> 0 | AH4: =SUM(AL3:AL153) -> 0 | AJ4: =IF(AND($AC$4<=$X4,$X4<$AD$4),Y4,0) -> 0 | AK4: =IF(AND($AC$4<=$X4,$X4<$AD$4),Z4,0) -> 0 | AL4: =IF(AND($AC$4<=$X4,$X4<$AD$4),AA4,0) -> 0 | AM4: =IF(AND($AC$5<=$X4,$X4<$AD$5),Y4,0) -> 0 | AN4: =IF(AND($AC$5<=$X4,$X4<$AD$5),Z4,0) -> 0 | AO4: =IF(AND($AC$5<=$X4,$X4<$AD$5),AA4,0) -> 0 | AP4: =IF(AND($AC$6<=$X4,$X4<$AD$6),Y4,0) -> 0 | AQ4: =IF(AND($AC$6<=$X4,$X4<$AD$6),Z4,0) -> 0 | AR4: =IF(AND($AC$6<=$X4,$X4<$AD$6),AA4,0) -> 0 | AS4: =IF(AND($AC$7<=$X4,$X4<$AD$7),Y4,0) -> 0 | AT4: =IF(AND($AC$7<=$X4,$X4<$AD$7),Z4,0) -> 0 | AU4: =IF(AND($AC$7<=$X4,$X4<$AD$7),AA4,0) -> 0 | AV4: =IF(AND($AC$8<=$X4,$X4<$AD$8),Y4,0) -> 0 | AW4: =IF(AND($AC$8<=$X4,$X4<$AD$8),Z4,0) -> 0 | AX4: =IF(AND($AC$8<=$X4,$X4<$AD$8),AA4,0) -> 0 | AY4: =IF(AND($AC$9<=$X4,$X4<$AD$9),Y4,0) -> 0 | AZ4: =IF(AND($AC$9<=$X4,$X4<$AD$9),Z4,0) -> 0 | BA4: =IF(AND($AC$9<=$X4,$X4<$AD$9),AA4,0) -> 0 | BB4: =IF(AND($AC$10<=$X4,$X4<$AD$10),Y4,0) -> 0 | BC4: =IF(AND($AC$10<=$X4,$X4<$AD$10),Z4,0) -> 0 | BD4: =IF(AND($AC$10<=$X4,$X4<$AD$10),AA4,0) -> 0 | BE4: =IF(AND($AC$11<=$X4,$X4<$AD$11),Y4,0) -> 0 | BF4: =IF(AND($AC$11<=$X4,$X4<$AD$11),Z4,0) -> 0 | BG4: =IF(AND($AC$11<=$X4,$X4<$AD$11),AA4,0) -> 0 | BH4: =IF(AND($AC$12<=$X4,$X4<$AD$12),Y4,0) -> 0 | BI4: =IF(AND($AC$12<=$X4,$X4<$AD$12),Z4,0) -> 0 | BJ4: =IF(AND($AC$12<=$X4,$X4<$AD$12),AA4,0) -> 0 | BK4: =IF(AND($AC$13<=$X4,$X4<$AD$13),Y4,0) -> 0 | BL4: =IF(AND($AC$13<=$X4,$X4<$AD$13),Z4,0) -> 0 | BM4: =IF(AND($AC$13<=$X4,$X4<$AD$13),AA4,0) -> 0 | BN4: =IF(AND($AC$14<=$X4,$X4<$AD$14),Y4,0) -> 0 | BO4: =IF(AND($AC$14<=$X4,$X4<$AD$14),Z4,0) -> 0 | BP4: =IF(AND($AC$14<=$X4,$X4<$AD$14),AA4,0) -> 0 | BQ4: =IF(AND($AC$15<=$X4,$X4<$AD$15),Y4,0) -> 0 | BR4: =IF(AND($AC$15<=$X4,$X4<$AD$15),Z4,0) -> 0 | BS4: =IF(AND($AC$15<=$X4,$X4<$AD$15),AA4,0) -> 0 | BT4: =IF(AND($AC$16<=$X4,$X4<$AD$16),Y4,0) -> 0 | BU4: =IF(AND($AC$16<=$X4,$X4<$AD$16),Z4,0) -> 0 | BV4: =IF(AND($AC$16<=$X4,$X4<$AD$16),AA4,0) -> 0 | BW4: =IF(AND($AC$17<=$X4,$X4<$AD$17),Y4,0) -> 0 | BX4: =IF(AND($AC$17<=$X4,$X4<$AD$17),Z4,0) -> 0 | BY4: =IF(AND($AC$17<=$X4,$X4<$AD$17),AA4,0) -> 0 | BZ4: =IF(AND($AC$18<=$X4,$X4<$AD$18),Y4,0) -> 0 | CA4: =IF(AND($AC$18<=$X4,$X4<$AD$18),Z4,0) -> 0 | CB4: =IF(AND($AC$18<=$X4,$X4<$AD$18),AA4,0) -> 0
B5: =IF('Summary Statistics'!$C$6=TRUE,Artists!$F4<B$3,Artists!$E4<B$3) -> FALSE | C5: =IF('Summary Statistics'!$C$6=TRUE,Artists!$F4<C$3,Artists!$E4<C$3) -> FALSE | D5: =IF('Summary Statistics'!$C$6=TRUE,Artists!$F4<D$3,Artists!$E4<D$3) -> FALSE | E5: =IF('Summary Statistics'!$C$6=TRUE,Artists!$F4<E$3,Artists!$E4<E$3) -> FALSE | F5: =IF('Summary Statistics'!$C$6=TRUE,Artists!$F4<F$3,Artists!$E4<F$3) -> FALSE | G5: =IF('Summary Statistics'!$C$6=TRUE,Artists!$F4<G$3,Artists!$E4<G$3) -> FALSE | H5: =IF('Summary Statistics'!$C$6=TRUE,Artists!$F4<H$3,Artists!$E4<H$3) -> FALSE | I5: =IF('Summary Statistics'!$C$6=TRUE,Artists!$F4<I$3,Artists!$E4<I$3) -> FALSE | ... K5: =IF('Summary Statistics'!$C$6=TRUE,Artists!$F4<K$3,Artists!$E4<K$3) -> FALSE | M5: =IF('Summary Statistics'!$C$7=TRUE,Albums!$F4<M$3,Albums!$E4<M$3) -> FALSE | N5: =IF('Summary Statistics'!$C$7=TRUE,Albums!$F4<N$3,Albums!$E4<N$3) -> FALSE | O5: =IF('Summary Statistics'!$C$7=TRUE,Albums!$F4<O$3,Albums!$E4<O$3) -> FALSE | P5: =IF('Summary Statistics'!$C$7=TRUE,Albums!$F4<P$3,Albums!$E4<P$3) -> FALSE | Q5: =IF('Summary Statistics'!$C$7=TRUE,Albums!$F4<Q$3,Albums!$E4<Q$3) -> FALSE | R5: =IF('Summary Statistics'!$C$7=TRUE,Albums!$F4<R$3,Albums!$E4<R$3) -> FALSE | S5: =IF('Summary Statistics'!$C$7=TRUE,Albums!$F4<S$3,Albums!$E4<S$3) -> FALSE | T5: =IF('Summary Statistics'!$C$7=TRUE,Albums!$F4<T$3,Albums!$E4<T$3) -> FALSE | ... V5: =IF('Summary Statistics'!$C$7=TRUE,Albums!$F4<V$3,Albums!$E4<V$3) -> FALSE | X5: =1+X4 -> 1902 | Y5: =COUNTIF('Cleaned Data'!$K$4:$K$5004,X5) -> 0 | Z5: =SUMIF('Cleaned Data'!$K$4:'Cleaned Data'!$K$5004,Calculations!X5,'Cleaned Data'!$J$4:$J$5004) -> 0 | AA5: =SUMIF('Cleaned Data'!$K$4:'Cleaned Data'!$K$5004,Calculations!X5,'Cleaned Data'!$H$4:$H$5004) -> 0 | AC5: 1910 | AD5: 1920 | AE5: 1910s | AF5: =SUM(AM3:AM153) -> 0 | AG5: =SUM(AN3:AN153) -> 0 | AH5: =SUM(AO3:AO153) -> 0 | AJ5: =IF(AND($AC$4<=$X5,$X5<$AD$4),Y5,0) -> 0 | AK5: =IF(AND($AC$4<=$X5,$X5<$AD$4),Z5,0) -> 0 | AL5: =IF(AND($AC$4<=$X5,$X5<$AD$4),AA5,0) -> 0 | AM5: =IF(AND($AC$5<=$X5,$X5<$AD$5),Y5,0) -> 0 | AN5: =IF(AND($AC$5<=$X5,$X5<$AD$5),Z5,0) -> 0 | AO5: =IF(AND($AC$5<=$X5,$X5<$AD$5),AA5,0) -> 0 | AP5: =IF(AND($AC$6<=$X5,$X5<$AD$6),Y5,0) -> 0 | AQ5: =IF(AND($AC$6<=$X5,$X5<$AD$6),Z5,0) -> 0 | AR5: =IF(AND($AC$6<=$X5,$X5<$AD$6),AA5,0) -> 0 | AS5: =IF(AND($AC$7<=$X5,$X5<$AD$7),Y5,0) -> 0 | AT5: =IF(AND($AC$7<=$X5,$X5<$AD$7),Z5,0) -> 0 | AU5: =IF(AND($AC$7<=$X5,$X5<$AD$7),AA5,0) -> 0 | AV5: =IF(AND($AC$8<=$X5,$X5<$AD$8),Y5,0) -> 0 | AW5: =IF(AND($AC$8<=$X5,$X5<$AD$8),Z5,0) -> 0 | AX5: =IF(AND($AC$8<=$X5,$X5<$AD$8),AA5,0) -> 0 | AY5: =IF(AND($AC$9<=$X5,$X5<$AD$9),Y5,0) -> 0 | AZ5: =IF(AND($AC$9<=$X5,$X5<$AD$9),Z5,0) -> 0 | BA5: =IF(AND($AC$9<=$X5,$X5<$AD$9),AA5,0) -> 0 | BB5: =IF(AND($AC$10<=$X5,$X5<$AD$10),Y5,0) -> 0 | BC5: =IF(AND($AC$10<=$X5,$X5<$AD$10),Z5,0) -> 0 | BD5: =IF(AND($AC$10<=$X5,$X5<$AD$10),AA5,0) -> 0 | BE5: =IF(AND($AC$11<=$X5,$X5<$AD$11),Y5,0) -> 0 | BF5: =IF(AND($AC$11<=$X5,$X5<$AD$11),Z5,0) -> 0 | BG5: =IF(AND($AC$11<=$X5,$X5<$AD$11),AA5,0) -> 0 | BH5: =IF(AND($AC$12<=$X5,$X5<$AD$12),Y5,0) -> 0 | BI5: =IF(AND($AC$12<=$X5,$X5<$AD$12),Z5,0) -> 0 | BJ5: =IF(AND($AC$12<=$X5,$X5<$AD$12),AA5,0) -> 0 | BK5: =IF(AND($AC$13<=$X5,$X5<$AD$13),Y5,0) -> 0 | BL5: =IF(AND($AC$13<=$X5,$X5<$AD$13),Z5,0) -> 0 | BM5: =IF(AND($AC$13<=$X5,$X5<$AD$13),AA5,0) -> 0 | BN5: =IF(AND($AC$14<=$X5,$X5<$AD$14),Y5,0) -> 0 | BO5: =IF(AND($AC$14<=$X5,$X5<$AD$14),Z5,0) -> 0 | BP5: =IF(AND($AC$14<=$X5,$X5<$AD$14),AA5,0) -> 0 | BQ5: =IF(AND($AC$15<=$X5,$X5<$AD$15),Y5,0) -> 0 | BR5: =IF(AND($AC$15<=$X5,$X5<$AD$15),Z5,0) -> 0 | BS5: =IF(AND($AC$15<=$X5,$X5<$AD$15),AA5,0) -> 0 | BT5: =IF(AND($AC$16<=$X5,$X5<$AD$16),Y5,0) -> 0 | BU5: =IF(AND($AC$16<=$X5,$X5<$AD$16),Z5,0) -> 0 | BV5: =IF(AND($AC$16<=$X5,$X5<$AD$16),AA5,0) -> 0 | BW5: =IF(AND($AC$17<=$X5,$X5<$AD$17),Y5,0) -> 0 | BX5: =IF(AND($AC$17<=$X5,$X5<$AD$17),Z5,0) -> 0 | BY5: =IF(AND($AC$17<=$X5,$X5<$AD$17),AA5,0) -> 0 | BZ5: =IF(AND($AC$18<=$X5,$X5<$AD$18),Y5,0) -> 0 | CA5: =IF(AND($AC$18<=$X5,$X5<$AD$18),Z5,0) -> 0 | CB5: =IF(AND($AC$18<=$X5,$X5<$AD$18),AA5,0) -> 0
B6: =IF('Summary Statistics'!$C$6=TRUE,Artists!$F5<B$3,Artists!$E5<B$3) -> FALSE | C6: =IF('Summary Statistics'!$C$6=TRUE,Artists!$F5<C$3,Artists!$E5<C$3) -> FALSE | D6: =IF('Summary Statistics'!$C$6=TRUE,Artists!$F5<D$3,Artists!$E5<D$3) -> FALSE | E6: =IF('Summary Statistics'!$C$6=TRUE,Artists!$F5<E$3,Artists!$E5<E$3) -> FALSE | F6: =IF('Summary Statistics'!$C$6=TRUE,Artists!$F5<F$3,Artists!$E5<F$3) -> FALSE | G6: =IF('Summary Statistics'!$C$6=TRUE,Artists!$F5<G$3,Artists!$E5<G$3) -> FALSE | H6: =IF('Summary Statistics'!$C$6=TRUE,Artists!$F5<H$3,Artists!$E5<H$3) -> FALSE | I6: =IF('Summary Statistics'!$C$6=TRUE,Artists!$F5<I$3,Artists!$E5<I$3) -> FALSE | ... K6: =IF('Summary Statistics'!$C$6=TRUE,Artists!$F5<K$3,Artists!$E5<K$3) -> FALSE | M6: =IF('Summary Statistics'!$C$7=TRUE,Albums!$F5<M$3,Albums!$E5<M$3) -> FALSE | N6: =IF('Summary Statistics'!$C$7=TRUE,Albums!$F5<N$3,Albums!$E5<N$3) -> FALSE | O6: =IF('Summary Statistics'!$C$7=TRUE,Albums!$F5<O$3,Albums!$E5<O$3) -> FALSE | P6: =IF('Summary Statistics'!$C$7=TRUE,Albums!$F5<P$3,Albums!$E5<P$3) -> FALSE | Q6: =IF('Summary Statistics'!$C$7=TRUE,Albums!$F5<Q$3,Albums!$E5<Q$3) -> FALSE | R6: =IF('Summary Statistics'!$C$7=TRUE,Albums!$F5<R$3,Albums!$E5<R$3) -> FALSE | S6: =IF('Summary Statistics'!$C$7=TRUE,Albums!$F5<S$3,Albums!$E5<S$3) -> FALSE | T6: =IF('Summary Statistics'!$C$7=TRUE,Albums!$F5<T$3,Albums!$E5<T$3) -> FALSE | ... V6: =IF('Summary Statistics'!$C$7=TRUE,Albums!$F5<V$3,Albums!$E5<V$3) -> FALSE | X6: =1+X5 -> 1903 | Y6: =COUNTIF('Cleaned Data'!$K$4:$K$5004,X6) -> 0 | Z6: =SUMIF('Cleaned Data'!$K$4:'Cleaned Data'!$K$5004,Calculations!X6,'Cleaned Data'!$J$4:$J$5004) -> 0 | AA6: =SUMIF('Cleaned Data'!$K$4:'Cleaned Data'!$K$5004,Calculations!X6,'Cleaned Data'!$H$4:$H$5004) -> 0 | AC6: 1920 | AD6: 1930 | AE6: 1920s | AF6: =SUM(AP3:AP153) -> 0 | AG6: =SUM(AQ3:AQ153) -> 0 | AH6: =SUM(AR3:AR153) -> 0 | AJ6: =IF(AND($AC$4<=$X6,$X6<$AD$4),Y6,0) -> 0 | AK6: =IF(AND($AC$4<=$X6,$X6<$AD$4),Z6,0) -> 0 | AL6: =IF(AND($AC$4<=$X6,$X6<$AD$4),AA6,0) -> 0 | AM6: =IF(AND($AC$5<=$X6,$X6<$AD$5),Y6,0) -> 0 | AN6: =IF(AND($AC$5<=$X6,$X6<$AD$5),Z6,0) -> 0 | AO6: =IF(AND($AC$5<=$X6,$X6<$AD$5),AA6,0) -> 0 | AP6: =IF(AND($AC$6<=$X6,$X6<$AD$6),Y6,0) -> 0 | AQ6: =IF(AND($AC$6<=$X6,$X6<$AD$6),Z6,0) -> 0 | AR6: =IF(AND($AC$6<=$X6,$X6<$AD$6),AA6,0) -> 0 | AS6: =IF(AND($AC$7<=$X6,$X6<$AD$7),Y6,0) -> 0 | AT6: =IF(AND($AC$7<=$X6,$X6<$AD$7),Z6,0) -> 0 | AU6: =IF(AND($AC$7<=$X6,$X6<$AD$7),AA6,0) -> 0 | AV6: =IF(AND($AC$8<=$X6,$X6<$AD$8),Y6,0) -> 0 | AW6: =IF(AND($AC$8<=$X6,$X6<$AD$8),Z6,0) -> 0 | AX6: =IF(AND($AC$8<=$X6,$X6<$AD$8),AA6,0) -> 0 | AY6: =IF(AND($AC$9<=$X6,$X6<$AD$9),Y6,0) -> 0 | AZ6: =IF(AND($AC$9<=$X6,$X6<$AD$9),Z6,0) -> 0 | BA6: =IF(AND($AC$9<=$X6,$X6<$AD$9),AA6,0) -> 0 | BB6: =IF(AND($AC$10<=$X6,$X6<$AD$10),Y6,0) -> 0 | BC6: =IF(AND($AC$10<=$X6,$X6<$AD$10),Z6,0) -> 0 | BD6: =IF(AND($AC$10<=$X6,$X6<$AD$10),AA6,0) -> 0 | BE6: =IF(AND($AC$11<=$X6,$X6<$AD$11),Y6,0) -> 0 | BF6: =IF(AND($AC$11<=$X6,$X6<$AD$11),Z6,0) -> 0 | BG6: =IF(AND($AC$11<=$X6,$X6<$AD$11),AA6,0) -> 0 | BH6: =IF(AND($AC$12<=$X6,$X6<$AD$12),Y6,0) -> 0 | BI6: =IF(AND($AC$12<=$X6,$X6<$AD$12),Z6,0) -> 0 | BJ6: =IF(AND($AC$12<=$X6,$X6<$AD$12),AA6,0) -> 0 | BK6: =IF(AND($AC$13<=$X6,$X6<$AD$13),Y6,0) -> 0 | BL6: =IF(AND($AC$13<=$X6,$X6<$AD$13),Z6,0) -> 0 | BM6: =IF(AND($AC$13<=$X6,$X6<$AD$13),AA6,0) -> 0 | BN6: =IF(AND($AC$14<=$X6,$X6<$AD$14),Y6,0) -> 0 | BO6: =IF(AND($AC$14<=$X6,$X6<$AD$14),Z6,0) -> 0 | BP6: =IF(AND($AC$14<=$X6,$X6<$AD$14),AA6,0) -> 0 | BQ6: =IF(AND($AC$15<=$X6,$X6<$AD$15),Y6,0) -> 0 | BR6: =IF(AND($AC$15<=$X6,$X6<$AD$15),Z6,0) -> 0 | BS6: =IF(AND($AC$15<=$X6,$X6<$AD$15),AA6,0) -> 0 | BT6: =IF(AND($AC$16<=$X6,$X6<$AD$16),Y6,0) -> 0 | BU6: =IF(AND($AC$16<=$X6,$X6<$AD$16),Z6,0) -> 0 | BV6: =IF(AND($AC$16<=$X6,$X6<$AD$16),AA6,0) -> 0 | BW6: =IF(AND($AC$17<=$X6,$X6<$AD$17),Y6,0) -> 0 | BX6: =IF(AND($AC$17<=$X6,$X6<$AD$17),Z6,0) -> 0 | BY6: =IF(AND($AC$17<=$X6,$X6<$AD$17),AA6,0) -> 0 | BZ6: =IF(AND($AC$18<=$X6,$X6<$AD$18),Y6,0) -> 0 | CA6: =IF(AND($AC$18<=$X6,$X6<$AD$18),Z6,0) -> 0 | CB6: =IF(AND($AC$18<=$X6,$X6<$AD$18),AA6,0) -> 0
B7: =IF('Summary Statistics'!$C$6=TRUE,Artists!$F6<B$3,Artists!$E6<B$3) -> FALSE | C7: =IF('Summary Statistics'!$C$6=TRUE,Artists!$F6<C$3,Artists!$E6<C$3) -> FALSE | D7: =IF('Summary Statistics'!$C$6=TRUE,Artists!$F6<D$3,Artists!$E6<D$3) -> FALSE | E7: =IF('Summary Statistics'!$C$6=TRUE,Artists!$F6<E$3,Artists!$E6<E$3) -> FALSE | F7: =IF('Summary Statistics'!$C$6=TRUE,Artists!$F6<F$3,Artists!$E6<F$3) -> FALSE | G7: =IF('Summary Statistics'!$C$6=TRUE,Artists!$F6<G$3,Artists!$E6<G$3) -> FALSE | H7: =IF('Summary Statistics'!$C$6=TRUE,Artists!$F6<H$3,Artists!$E6<H$3) -> FALSE | I7: =IF('Summary Statistics'!$C$6=TRUE,Artists!$F6<I$3,Artists!$E6<I$3) -> FALSE | ... K7: =IF('Summary Statistics'!$C$6=TRUE,Artists!$F6<K$3,Artists!$E6<K$3) -> FALSE | M7: =IF('Summary Statistics'!$C$7=TRUE,Albums!$F6<M$3,Albums!$E6<M$3) -> FALSE | N7: =IF('Summary Statistics'!$C$7=TRUE,Albums!$F6<N$3,Albums!$E6<N$3) -> FALSE | O7: =IF('Summary Statistics'!$C$7=TRUE,Albums!$F6<O$3,Albums!$E6<O$3) -> FALSE | P7: =IF('Summary Statistics'!$C$7=TRUE,Albums!$F6<P$3,Albums!$E6<P$3) -> FALSE | Q7: =IF('Summary Statistics'!$C$7=TRUE,Albums!$F6<Q$3,Albums!$E6<Q$3) -> FALSE | R7: =IF('Summary Statistics'!$C$7=TRUE,Albums!$F6<R$3,Albums!$E6<R$3) -> FALSE | S7: =IF('Summary Statistics'!$C$7=TRUE,Albums!$F6<S$3,Albums!$E6<S$3) -> FALSE | T7: =IF('Summary Statistics'!$C$7=TRUE,Albums!$F6<T$3,Albums!$E6<T$3) -> FALSE | ... V7: =IF('Summary Statistics'!$C$7=TRUE,Albums!$F6<V$3,Albums!$E6<V$3) -> FALSE | X7: =1+X6 -> 1904 | Y7: =COUNTIF('Cleaned Data'!$K$4:$K$5004,X7) -> 0 | Z7: =SUMIF('Cleaned Data'!$K$4:'Cleaned Data'!$K$5004,Calculations!X7,'Cleaned Data'!$J$4:$J$5004) -> 0 | AA7: =SUMIF('Cleaned Data'!$K$4:'Cleaned Data'!$K$5004,Calculations!X7,'Cleaned Data'!$H$4:$H$5004) -> 0 | AC7: 1930 | AD7: 1940 | AE7: 1930s | AF7: =SUM(AS3:AS153) -> 0 | AG7: =SUM(AT3:AT153) -> 0 | AH7: =SUM(AU3:AU153) -> 0 | AJ7: =IF(AND($AC$4<=$X7,$X7<$AD$4),Y7,0) -> 0 | AK7: =IF(AND($AC$4<=$X7,$X7<$AD$4),Z7,0) -> 0 | AL7: =IF(AND($AC$4<=$X7,$X7<$AD$4),AA7,0) -> 0 | AM7: =IF(AND($AC$5<=$X7,$X7<$AD$5),Y7,0) -> 0 | AN7: =IF(AND($AC$5<=$X7,$X7<$AD$5),Z7,0) -> 0 | AO7: =IF(AND($AC$5<=$X7,$X7<$AD$5),AA7,0) -> 0 | AP7: =IF(AND($AC$6<=$X7,$X7<$AD$6),Y7,0) -> 0 | AQ7: =IF(AND($AC$6<=$X7,$X7<$AD$6),Z7,0) -> 0 | AR7: =IF(AND($AC$6<=$X7,$X7<$AD$6),AA7,0) -> 0 | AS7: =IF(AND($AC$7<=$X7,$X7<$AD$7),Y7,0) -> 0 | AT7: =IF(AND($AC$7<=$X7,$X7<$AD$7),Z7,0) -> 0 | AU7: =IF(AND($AC$7<=$X7,$X7<$AD$7),AA7,0) -> 0 | AV7: =IF(AND($AC$8<=$X7,$X7<$AD$8),Y7,0) -> 0 | AW7: =IF(AND($AC$8<=$X7,$X7<$AD$8),Z7,0) -> 0 | AX7: =IF(AND($AC$8<=$X7,$X7<$AD$8),AA7,0) -> 0 | AY7: =IF(AND($AC$9<=$X7,$X7<$AD$9),Y7,0) -> 0 | AZ7: =IF(AND($AC$9<=$X7,$X7<$AD$9),Z7,0) -> 0 | BA7: =IF(AND($AC$9<=$X7,$X7<$AD$9),AA7,0) -> 0 | BB7: =IF(AND($AC$10<=$X7,$X7<$AD$10),Y7,0) -> 0 | BC7: =IF(AND($AC$10<=$X7,$X7<$AD$10),Z7,0) -> 0 | BD7: =IF(AND($AC$10<=$X7,$X7<$AD$10),AA7,0) -> 0 | BE7: =IF(AND($AC$11<=$X7,$X7<$AD$11),Y7,0) -> 0 | BF7: =IF(AND($AC$11<=$X7,$X7<$AD$11),Z7,0) -> 0 | BG7: =IF(AND($AC$11<=$X7,$X7<$AD$11),AA7,0) -> 0 | BH7: =IF(AND($AC$12<=$X7,$X7<$AD$12),Y7,0) -> 0 | BI7: =IF(AND($AC$12<=$X7,$X7<$AD$12),Z7,0) -> 0 | BJ7: =IF(AND($AC$12<=$X7,$X7<$AD$12),AA7,0) -> 0 | BK7: =IF(AND($AC$13<=$X7,$X7<$AD$13),Y7,0) -> 0 | BL7: =IF(AND($AC$13<=$X7,$X7<$AD$13),Z7,0) -> 0 | BM7: =IF(AND($AC$13<=$X7,$X7<$AD$13),AA7,0) -> 0 | BN7: =IF(AND($AC$14<=$X7,$X7<$AD$14),Y7,0) -> 0 | BO7: =IF(AND($AC$14<=$X7,$X7<$AD$14),Z7,0) -> 0 | BP7: =IF(AND($AC$14<=$X7,$X7<$AD$14),AA7,0) -> 0 | BQ7: =IF(AND($AC$15<=$X7,$X7<$AD$15),Y7,0) -> 0 | BR7: =IF(AND($AC$15<=$X7,$X7<$AD$15),Z7,0) -> 0 | BS7: =IF(AND($AC$15<=$X7,$X7<$AD$15),AA7,0) -> 0 | BT7: =IF(AND($AC$16<=$X7,$X7<$AD$16),Y7,0) -> 0 | BU7: =IF(AND($AC$16<=$X7,$X7<$AD$16),Z7,0) -> 0 | BV7: =IF(AND($AC$16<=$X7,$X7<$AD$16),AA7,0) -> 0 | BW7: =IF(AND($AC$17<=$X7,$X7<$AD$17),Y7,0) -> 0 | BX7: =IF(AND($AC$17<=$X7,$X7<$AD$17),Z7,0) -> 0 | BY7: =IF(AND($AC$17<=$X7,$X7<$AD$17),AA7,0) -> 0 | BZ7: =IF(AND($AC$18<=$X7,$X7<$AD$18),Y7,0) -> 0 | CA7: =IF(AND($AC$18<=$X7,$X7<$AD$18),Z7,0) -> 0 | CB7: =IF(AND($AC$18<=$X7,$X7<$AD$18),AA7,0) -> 0
B8: =IF('Summary Statistics'!$C$6=TRUE,Artists!$F7<B$3,Artists!$E7<B$3) -> FALSE | C8: =IF('Summary Statistics'!$C$6=TRUE,Artists!$F7<C$3,Artists!$E7<C$3) -> FALSE | D8: =IF('Summary Statistics'!$C$6=TRUE,Artists!$F7<D$3,Artists!$E7<D$3) -> FALSE | E8: =IF('Summary Statistics'!$C$6=TRUE,Artists!$F7<E$3,Artists!$E7<E$3) -> FALSE | F8: =IF('Summary Statistics'!$C$6=TRUE,Artists!$F7<F$3,Artists!$E7<F$3) -> FALSE | G8: =IF('Summary Statistics'!$C$6=TRUE,Artists!$F7<G$3,Artists!$E7<G$3) -> FALSE | H8: =IF('Summary Statistics'!$C$6=TRUE,Artists!$F7<H$3,Artists!$E7<H$3) -> FALSE | I8: =IF('Summary Statistics'!$C$6=TRUE,Artists!$F7<I$3,Artists!$E7<I$3) -> FALSE | ... K8: =IF('Summary Statistics'!$C$6=TRUE,Artists!$F7<K$3,Artists!$E7<K$3) -> FALSE | M8: =IF('Summary Statistics'!$C$7=TRUE,Albums!$F7<M$3,Albums!$E7<M$3) -> FALSE | N8: =IF('Summary Statistics'!$C$7=TRUE,Albums!$F7<N$3,Albums!$E7<N$3) -> FALSE | O8: =IF('Summary Statistics'!$C$7=TRUE,Albums!$F7<O$3,Albums!$E7<O$3) -> FALSE | P8: =IF('Summary Statistics'!$C$7=TRUE,Albums!$F7<P$3,Albums!$E7<P$3) -> FALSE | Q8: =IF('Summary Statistics'!$C$7=TRUE,Albums!$F7<Q$3,Albums!$E7<Q$3) -> FALSE | R8: =IF('Summary Statistics'!$C$7=TRUE,Albums!$F7<R$3,Albums!$E7<R$3) -> FALSE | S8: =IF('Summary Statistics'!$C$7=TRUE,Albums!$F7<S$3,Albums!$E7<S$3) -> FALSE | T8: =IF('Summary Statistics'!$C$7=TRUE,Albums!$F7<T$3,Albums!$E7<T$3) -> FALSE | ... V8: =IF('Summary Statistics'!$C$7=TRUE,Albums!$F7<V$3,Albums!$E7<V$3) -> FALSE | X8: =1+X7 -> 1905 | Y8: =COUNTIF('Cleaned Data'!$K$4:$K$5004,X8) -> 0 | Z8: =SUMIF('Cleaned Data'!$K$4:'Cleaned Data'!$K$5004,Calculations!X8,'Cleaned Data'!$J$4:$J$5004) -> 0 | AA8: =SUMIF('Cleaned Data'!$K$4:'Cleaned Data'!$K$5004,Calculations!X8,'Cleaned Data'!$H$4:$H$5004) -> 0 | AC8: 1940 | AD8: 1950 | AE8: 1940s | AF8: =SUM(AV3:AV153) -> 0 | AG8: =SUM(AW3:AW153) -> 0 | AH8: =SUM(AX3:AX153) -> 0 | AJ8: =IF(AND($AC$4<=$X8,$X8<$AD$4),Y8,0) -> 0 | AK8: =IF(AND($AC$4<=$X8,$X8<$AD$4),Z8,0) -> 0 | AL8: =IF(AND($AC$4<=$X8,$X8<$AD$4),AA8,0) -> 0 | AM8: =IF(AND($AC$5<=$X8,$X8<$AD$5),Y8,0) -> 0 | AN8: =IF(AND($AC$5<=$X8,$X8<$AD$5),Z8,0) -> 0 | AO8: =IF(AND($AC$5<=$X8,$X8<$AD$5),AA8,0) -> 0 | AP8: =IF(AND($AC$6<=$X8,$X8<$AD$6),Y8,0) -> 0 | AQ8: =IF(AND($AC$6<=$X8,$X8<$AD$6),Z8,0) -> 0 | AR8: =IF(AND($AC$6<=$X8,$X8<$AD$6),AA8,0) -> 0 | AS8: =IF(AND($AC$7<=$X8,$X8<$AD$7),Y8,0) -> 0 | AT8: =IF(AND($AC$7<=$X8,$X8<$AD$7),Z8,0) -> 0 | AU8: =IF(AND($AC$7<=$X8,$X8<$AD$7),AA8,0) -> 0 | AV8: =IF(AND($AC$8<=$X8,$X8<$AD$8),Y8,0) -> 0 | AW8: =IF(AND($AC$8<=$X8,$X8<$AD$8),Z8,0) -> 0 | AX8: =IF(AND($AC$8<=$X8,$X8<$AD$8),AA8,0) -> 0 | AY8: =IF(AND($AC$9<=$X8,$X8<$AD$9),Y8,0) -> 0 | AZ8: =IF(AND($AC$9<=$X8,$X8<$AD$9),Z8,0) -> 0 | BA8: =IF(AND($AC$9<=$X8,$X8<$AD$9),AA8,0) -> 0 | BB8: =IF(AND($AC$10<=$X8,$X8<$AD$10),Y8,0) -> 0 | BC8: =IF(AND($AC$10<=$X8,$X8<$AD$10),Z8,0) -> 0 | BD8: =IF(AND($AC$10<=$X8,$X8<$AD$10),AA8,0) -> 0 | BE8: =IF(AND($AC$11<=$X8,$X8<$AD$11),Y8,0) -> 0 | BF8: =IF(AND($AC$11<=$X8,$X8<$AD$11),Z8,0) -> 0 | BG8: =IF(AND($AC$11<=$X8,$X8<$AD$11),AA8,0) -> 0 | BH8: =IF(AND($AC$12<=$X8,$X8<$AD$12),Y8,0) -> 0 | BI8: =IF(AND($AC$12<=$X8,$X8<$AD$12),Z8,0) -> 0 | BJ8: =IF(AND($AC$12<=$X8,$X8<$AD$12),AA8,0) -> 0 | BK8: =IF(AND($AC$13<=$X8,$X8<$AD$13),Y8,0) -> 0 | BL8: =IF(AND($AC$13<=$X8,$X8<$AD$13),Z8,0) -> 0 | BM8: =IF(AND($AC$13<=$X8,$X8<$AD$13),AA8,0) -> 0 | BN8: =IF(AND($AC$14<=$X8,$X8<$AD$14),Y8,0) -> 0 | BO8: =IF(AND($AC$14<=$X8,$X8<$AD$14),Z8,0) -> 0 | BP8: =IF(AND($AC$14<=$X8,$X8<$AD$14),AA8,0) -> 0 | BQ8: =IF(AND($AC$15<=$X8,$X8<$AD$15),Y8,0) -> 0 | BR8: =IF(AND($AC$15<=$X8,$X8<$AD$15),Z8,0) -> 0 | BS8: =IF(AND($AC$15<=$X8,$X8<$AD$15),AA8,0) -> 0 | BT8: =IF(AND($AC$16<=$X8,$X8<$AD$16),Y8,0) -> 0 | BU8: =IF(AND($AC$16<=$X8,$X8<$AD$16),Z8,0) -> 0 | BV8: =IF(AND($AC$16<=$X8,$X8<$AD$16),AA8,0) -> 0 | BW8: =IF(AND($AC$17<=$X8,$X8<$AD$17),Y8,0) -> 0 | BX8: =IF(AND($AC$17<=$X8,$X8<$AD$17),Z8,0) -> 0 | BY8: =IF(AND($AC$17<=$X8,$X8<$AD$17),AA8,0) -> 0 | BZ8: =IF(AND($AC$18<=$X8,$X8<$AD$18),Y8,0) -> 0 | CA8: =IF(AND($AC$18<=$X8,$X8<$AD$18),Z8,0) -> 0 | CB8: =IF(AND($AC$18<=$X8,$X8<$AD$18),AA8,0) -> 0
B9: =IF('Summary Statistics'!$C$6=TRUE,Artists!$F8<B$3,Artists!$E8<B$3) -> FALSE | C9: =IF('Summary Statistics'!$C$6=TRUE,Artists!$F8<C$3,Artists!$E8<C$3) -> FALSE | D9: =IF('Summary Statistics'!$C$6=TRUE,Artists!$F8<D$3,Artists!$E8<D$3) -> FALSE | E9: =IF('Summary Statistics'!$C$6=TRUE,Artists!$F8<E$3,Artists!$E8<E$3) -> FALSE | F9: =IF('Summary Statistics'!$C$6=TRUE,Artists!$F8<F$3,Artists!$E8<F$3) -> FALSE | G9: =IF('Summary Statistics'!$C$6=TRUE,Artists!$F8<G$3,Artists!$E8<G$3) -> FALSE | H9: =IF('Summary Statistics'!$C$6=TRUE,Artists!$F8<H$3,Artists!$E8<H$3) -> FALSE | I9: =IF('Summary Statistics'!$C$6=TRUE,Artists!$F8<I$3,Artists!$E8<I$3) -> FALSE | ... K9: =IF('Summary Statistics'!$C$6=TRUE,Artists!$F8<K$3,Artists!$E8<K$3) -> FALSE | M9: =IF('Summary Statistics'!$C$7=TRUE,Albums!$F8<M$3,Albums!$E8<M$3) -> FALSE | N9: =IF('Summary Statistics'!$C$7=TRUE,Albums!$F8<N$3,Albums!$E8<N$3) -> FALSE | O9: =IF('Summary Statistics'!$C$7=TRUE,Albums!$F8<O$3,Albums!$E8<O$3) -> FALSE | P9: =IF('Summary Statistics'!$C$7=TRUE,Albums!$F8<P$3,Albums!$E8<P$3) -> FALSE | Q9: =IF('Summary Statistics'!$C$7=TRUE,Albums!$F8<Q$3,Albums!$E8<Q$3) -> FALSE | R9: =IF('Summary Statistics'!$C$7=TRUE,Albums!$F8<R$3,Albums!$E8<R$3) -> FALSE | S9: =IF('Summary Statistics'!$C$7=TRUE,Albums!$F8<S$3,Albums!$E8<S$3) -> FALSE | T9: =IF('Summary Statistics'!$C$7=TRUE,Albums!$F8<T$3,Albums!$E8<T$3) -> FALSE | ... V9: =IF('Summary Statistics'!$C$7=TRUE,Albums!$F8<V$3,Albums!$E8<V$3) -> FALSE | X9: =1+X8 -> 1906 | Y9: =COUNTIF('Cleaned Data'!$K$4:$K$5004,X9) -> 0 | Z9: =SUMIF('Cleaned Data'!$K$4:'Cleaned Data'!$K$5004,Calculations!X9,'Cleaned Data'!$J$4:$J$5004) -> 0 | AA9: =SUMIF('Cleaned Data'!$K$4:'Cleaned Data'!$K$5004,Calculations!X9,'Cleaned Data'!$H$4:$H$5004) -> 0 | AC9: 1950 | AD9: 1960 | AE9: 1950s | AF9: =SUM(AY3:AY153) -> 0 | AG9: =SUM(AZ3:AZ153) -> 0 | AH9: =SUM(BA3:BA153) -> 0 | AJ9: =IF(AND($AC$4<=$X9,$X9<$AD$4),Y9,0) -> 0 | AK9: =IF(AND($AC$4<=$X9,$X9<$AD$4),Z9,0) -> 0 | AL9: =IF(AND($AC$4<=$X9,$X9<$AD$4),AA9,0) -> 0 | AM9: =IF(AND($AC$5<=$X9,$X9<$AD$5),Y9,0) -> 0 | AN9: =IF(AND($AC$5<=$X9,$X9<$AD$5),Z9,0) -> 0 | AO9: =IF(AND($AC$5<=$X9,$X9<$AD$5),AA9,0) -> 0 | AP9: =IF(AND($AC$6<=$X9,$X9<$AD$6),Y9,0) -> 0 | AQ9: =IF(AND($AC$6<=$X9,$X9<$AD$6),Z9,0) -> 0 | AR9: =IF(AND($AC$6<=$X9,$X9<$AD$6),AA9,0) -> 0 | AS9: =IF(AND($AC$7<=$X9,$X9<$AD$7),Y9,0) -> 0 | AT9: =IF(AND($AC$7<=$X9,$X9<$AD$7),Z9,0) -> 0 | AU9: =IF(AND($AC$7<=$X9,$X9<$AD$7),AA9,0) -> 0 | AV9: =IF(AND($AC$8<=$X9,$X9<$AD$8),Y9,0) -> 0 | AW9: =IF(AND($AC$8<=$X9,$X9<$AD$8),Z9,0) -> 0 | AX9: =IF(AND($AC$8<=$X9,$X9<$AD$8),AA9,0) -> 0 | AY9: =IF(AND($AC$9<=$X9,$X9<$AD$9),Y9,0) -> 0 | AZ9: =IF(AND($AC$9<=$X9,$X9<$AD$9),Z9,0) -> 0 | BA9: =IF(AND($AC$9<=$X9,$X9<$AD$9),AA9,0) -> 0 | BB9: =IF(AND($AC$10<=$X9,$X9<$AD$10),Y9,0) -> 0 | BC9: =IF(AND($AC$10<=$X9,$X9<$AD$10),Z9,0) -> 0 | BD9: =IF(AND($AC$10<=$X9,$X9<$AD$10),AA9,0) -> 0 | BE9: =IF(AND($AC$11<=$X9,$X9<$AD$11),Y9,0) -> 0 | BF9: =IF(AND($AC$11<=$X9,$X9<$AD$11),Z9,0) -> 0 | BG9: =IF(AND($AC$11<=$X9,$X9<$AD$11),AA9,0) -> 0 | BH9: =IF(AND($AC$12<=$X9,$X9<$AD$12),Y9,0) -> 0 | BI9: =IF(AND($AC$12<=$X9,$X9<$AD$12),Z9,0) -> 0 | BJ9: =IF(AND($AC$12<=$X9,$X9<$AD$12),AA9,0) -> 0 | BK9: =IF(AND($AC$13<=$X9,$X9<$AD$13),Y9,0) -> 0 | BL9: =IF(AND($AC$13<=$X9,$X9<$AD$13),Z9,0) -> 0 | BM9: =IF(AND($AC$13<=$X9,$X9<$AD$13),AA9,0) -> 0 | BN9: =IF(AND($AC$14<=$X9,$X9<$AD$14),Y9,0) -> 0 | BO9: =IF(AND($AC$14<=$X9,$X9<$AD$14),Z9,0) -> 0 | BP9: =IF(AND($AC$14<=$X9,$X9<$AD$14),AA9,0) -> 0 | BQ9: =IF(AND($AC$15<=$X9,$X9<$AD$15),Y9,0) -> 0 | BR9: =IF(AND($AC$15<=$X9,$X9<$AD$15),Z9,0) -> 0 | BS9: =IF(AND($AC$15<=$X9,$X9<$AD$15),AA9,0) -> 0 | BT9: =IF(AND($AC$16<=$X9,$X9<$AD$16),Y9,0) -> 0 | BU9: =IF(AND($AC$16<=$X9,$X9<$AD$16),Z9,0) -> 0 | BV9: =IF(AND($AC$16<=$X9,$X9<$AD$16),AA9,0) -> 0 | BW9: =IF(AND($AC$17<=$X9,$X9<$AD$17),Y9,0) -> 0 | BX9: =IF(AND($AC$17<=$X9,$X9<$AD$17),Z9,0) -> 0 | BY9: =IF(AND($AC$17<=$X9,$X9<$AD$17),AA9,0) -> 0 | BZ9: =IF(AND($AC$18<=$X9,$X9<$AD$18),Y9,0) -> 0 | CA9: =IF(AND($AC$18<=$X9,$X9<$AD$18),Z9,0) -> 0 | CB9: =IF(AND($AC$18<=$X9,$X9<$AD$18),AA9,0) -> 0
B10: =IF('Summary Statistics'!$C$6=TRUE,Artists!$F9<B$3,Artists!$E9<B$3) -> FALSE | C10: =IF('Summary Statistics'!$C$6=TRUE,Artists!$F9<C$3,Artists!$E9<C$3) -> FALSE | D10: =IF('Summary Statistics'!$C$6=TRUE,Artists!$F9<D$3,Artists!$E9<D$3) -> FALSE | E10: =IF('Summary Statistics'!$C$6=TRUE,Artists!$F9<E$3,Artists!$E9<E$3) -> FALSE | F10: =IF('Summary Statistics'!$C$6=TRUE,Artists!$F9<F$3,Artists!$E9<F$3) -> FALSE | G10: =IF('Summary Statistics'!$C$6=TRUE,Artists!$F9<G$3,Artists!$E9<G$3) -> FALSE | H10: =IF('Summary Statistics'!$C$6=TRUE,Artists!$F9<H$3,Artists!$E9<H$3) -> FALSE | I10: =IF('Summary Statistics'!$C$6=TRUE,Artists!$F9<I$3,Artists!$E9<I$3) -> FALSE | ... K10: =IF('Summary Statistics'!$C$6=TRUE,Artists!$F9<K$3,Artists!$E9<K$3) -> FALSE | M10: =IF('Summary Statistics'!$C$7=TRUE,Albums!$F9<M$3,Albums!$E9<M$3) -> FALSE | N10: =IF('Summary Statistics'!$C$7=TRUE,Albums!$F9<N$3,Albums!$E9<N$3) -> FALSE | O10: =IF('Summary Statistics'!$C$7=TRUE,Albums!$F9<O$3,Albums!$E9<O$3) -> FALSE | P10: =IF('Summary Statistics'!$C$7=TRUE,Albums!$F9<P$3,Albums!$E9<P$3) -> FALSE | Q10: =IF('Summary Statistics'!$C$7=TRUE,Albums!$F9<Q$3,Albums!$E9<Q$3) -> FALSE | R10: =IF('Summary Statistics'!$C$7=TRUE,Albums!$F9<R$3,Albums!$E9<R$3) -> FALSE | S10: =IF('Summary Statistics'!$C$7=TRUE,Albums!$F9<S$3,Albums!$E9<S$3) -> FALSE | T10: =IF('Summary Statistics'!$C$7=TRUE,Albums!$F9<T$3,Albums!$E9<T$3) -> FALSE | ... V10: =IF('Summary Statistics'!$C$7=TRUE,Albums!$F9<V$3,Albums!$E9<V$3) -> FALSE | X10: =1+X9 -> 1907 | Y10: =COUNTIF('Cleaned Data'!$K$4:$K$5004,X10) -> 0 | Z10: =SUMIF('Cleaned Data'!$K$4:'Cleaned Data'!$K$5004,Calculations!X10,'Cleaned Data'!$J$4:$J$5004) -> 0 | AA10: =SUMIF('Cleaned Data'!$K$4:'Cleaned Data'!$K$5004,Calculations!X10,'Cleaned Data'!$H$4:$H$5004) -> 0 | AC10: 1960 | AD10: 1970 | AE10: 1960s | AF10: =SUM(BB3:BB153) -> 0 | AG10: =SUM(BC3:BC153) -> 0 | AH10: =SUM(BD3:BD153) -> 0 | AJ10: =IF(AND($AC$4<=$X10,$X10<$AD$4),Y10,0) -> 0 | AK10: =IF(AND($AC$4<=$X10,$X10<$AD$4),Z10,0) -> 0 | AL10: =IF(AND($AC$4<=$X10,$X10<$AD$4),AA10,0) -> 0 | AM10: =IF(AND($AC$5<=$X10,$X10<$AD$5),Y10,0) -> 0 | AN10: =IF(AND($AC$5<=$X10,$X10<$AD$5),Z10,0) -> 0 | AO10: =IF(AND($AC$5<=$X10,$X10<$AD$5),AA10,0) -> 0 | AP10: =IF(AND($AC$6<=$X10,$X10<$AD$6),Y10,0) -> 0 | AQ10: =IF(AND($AC$6<=$X10,$X10<$AD$6),Z10,0) -> 0 | AR10: =IF(AND($AC$6<=$X10,$X10<$AD$6),AA10,0) -> 0 | AS10: =IF(AND($AC$7<=$X10,$X10<$AD$7),Y10,0) -> 0 | AT10: =IF(AND($AC$7<=$X10,$X10<$AD$7),Z10,0) -> 0 | AU10: =IF(AND($AC$7<=$X10,$X10<$AD$7),AA10,0) -> 0 | AV10: =IF(AND($AC$8<=$X10,$X10<$AD$8),Y10,0) -> 0 | AW10: =IF(AND($AC$8<=$X10,$X10<$AD$8),Z10,0) -> 0 | AX10: =IF(AND($AC$8<=$X10,$X10<$AD$8),AA10,0) -> 0 | AY10: =IF(AND($AC$9<=$X10,$X10<$AD$9),Y10,0) -> 0 | AZ10: =IF(AND($AC$9<=$X10,$X10<$AD$9),Z10,0) -> 0 | BA10: =IF(AND($AC$9<=$X10,$X10<$AD$9),AA10,0) -> 0 | BB10: =IF(AND($AC$10<=$X10,$X10<$AD$10),Y10,0) -> 0 | BC10: =IF(AND($AC$10<=$X10,$X10<$AD$10),Z10,0) -> 0 | BD10: =IF(AND($AC$10<=$X10,$X10<$AD$10),AA10,0) -> 0 | BE10: =IF(AND($AC$11<=$X10,$X10<$AD$11),Y10,0) -> 0 | BF10: =IF(AND($AC$11<=$X10,$X10<$AD$11),Z10,0) -> 0 | BG10: =IF(AND($AC$11<=$X10,$X10<$AD$11),AA10,0) -> 0 | BH10: =IF(AND($AC$12<=$X10,$X10<$AD$12),Y10,0) -> 0 | BI10: =IF(AND($AC$12<=$X10,$X10<$AD$12),Z10,0) -> 0 | BJ10: =IF(AND($AC$12<=$X10,$X10<$AD$12),AA10,0) -> 0 | BK10: =IF(AND($AC$13<=$X10,$X10<$AD$13),Y10,0) -> 0 | BL10: =IF(AND($AC$13<=$X10,$X10<$AD$13),Z10,0) -> 0 | BM10: =IF(AND($AC$13<=$X10,$X10<$AD$13),AA10,0) -> 0 | BN10: =IF(AND($AC$14<=$X10,$X10<$AD$14),Y10,0) -> 0 | BO10: =IF(AND($AC$14<=$X10,$X10<$AD$14),Z10,0) -> 0 | BP10: =IF(AND($AC$14<=$X10,$X10<$AD$14),AA10,0) -> 0 | BQ10: =IF(AND($AC$15<=$X10,$X10<$AD$15),Y10,0) -> 0 | BR10: =IF(AND($AC$15<=$X10,$X10<$AD$15),Z10,0) -> 0 | BS10: =IF(AND($AC$15<=$X10,$X10<$AD$15),AA10,0) -> 0 | BT10: =IF(AND($AC$16<=$X10,$X10<$AD$16),Y10,0) -> 0 | BU10: =IF(AND($AC$16<=$X10,$X10<$AD$16),Z10,0) -> 0 | BV10: =IF(AND($AC$16<=$X10,$X10<$AD$16),AA10,0) -> 0 | BW10: =IF(AND($AC$17<=$X10,$X10<$AD$17),Y10,0) -> 0 | BX10: =IF(AND($AC$17<=$X10,$X10<$AD$17),Z10,0) -> 0 | BY10: =IF(AND($AC$17<=$X10,$X10<$AD$17),AA10,0) -> 0 | BZ10: =IF(AND($AC$18<=$X10,$X10<$AD$18),Y10,0) -> 0 | CA10: =IF(AND($AC$18<=$X10,$X10<$AD$18),Z10,0) -> 0 | CB10: =IF(AND($AC$18<=$X10,$X10<$AD$18),AA10,0) -> 0
B11: =IF('Summary Statistics'!$C$6=TRUE,Artists!$F10<B$3,Artists!$E10<B$3) -> FALSE | C11: =IF('Summary Statistics'!$C$6=TRUE,Artists!$F10<C$3,Artists!$E10<C$3) -> FALSE | D11: =IF('Summary Statistics'!$C$6=TRUE,Artists!$F10<D$3,Artists!$E10<D$3) -> FALSE | E11: =IF('Summary Statistics'!$C$6=TRUE,Artists!$F10<E$3,Artists!$E10<E$3) -> FALSE | F11: =IF('Summary Statistics'!$C$6=TRUE,Artists!$F10<F$3,Artists!$E10<F$3) -> FALSE | G11: =IF('Summary Statistics'!$C$6=TRUE,Artists!$F10<G$3,Artists!$E10<G$3) -> FALSE | H11: =IF('Summary Statistics'!$C$6=TRUE,Artists!$F10<H$3,Artists!$E10<H$3) -> FALSE | I11: =IF('Summary Statistics'!$C$6=TRUE,Artists!$F10<I$3,Artists!$E10<I$3) -> FALSE | ... K11: =IF('Summary Statistics'!$C$6=TRUE,Artists!$F10<K$3,Artists!$E10<K$3) -> FALSE | M11: =IF('Summary Statistics'!$C$7=TRUE,Albums!$F10<M$3,Albums!$E10<M$3) -> FALSE | N11: =IF('Summary Statistics'!$C$7=TRUE,Albums!$F10<N$3,Albums!$E10<N$3) -> FALSE | O11: =IF('Summary Statistics'!$C$7=TRUE,Albums!$F10<O$3,Albums!$E10<O$3) -> FALSE | P11: =IF('Summary Statistics'!$C$7=TRUE,Albums!$F10<P$3,Albums!$E10<P$3) -> FALSE | Q11: =IF('Summary Statistics'!$C$7=TRUE,Albums!$F10<Q$3,Albums!$E10<Q$3) -> FALSE | R11: =IF('Summary Statistics'!$C$7=TRUE,Albums!$F10<R$3,Albums!$E10<R$3) -> FALSE | S11: =IF('Summary Statistics'!$C$7=TRUE,Albums!$F10<S$3,Albums!$E10<S$3) -> FALSE | T11: =IF('Summary Statistics'!$C$7=TRUE,Albums!$F10<T$3,Albums!$E10<T$3) -> FALSE | ... V11: =IF('Summary Statistics'!$C$7=TRUE,Albums!$F10<V$3,Albums!$E10<V$3) -> FALSE | X11: =1+X10 -> 1908 | Y11: =COUNTIF('Cleaned Data'!$K$4:$K$5004,X11) -> 0 | Z11: =SUMIF('Cleaned Data'!$K$4:'Cleaned Data'!$K$5004,Calculations!X11,'Cleaned Data'!$J$4:$J$5004) -> 0 | AA11: =SUMIF('Cleaned Data'!$K$4:'Cleaned Data'!$K$5004,Calculations!X11,'Cleaned Data'!$H$4:$H$5004) -> 0 | AC11: 1970 | AD11: 1980 | AE11: 1970s | AF11: =SUM(BE3:BE153) -> 0 | AG11: =SUM(BF3:BF153) -> 0 | AH11: =SUM(BG3:BG153) -> 0 | AJ11: =IF(AND($AC$4<=$X11,$X11<$AD$4),Y11,0) -> 0 | AK11: =IF(AND($AC$4<=$X11,$X11<$AD$4),Z11,0) -> 0 | AL11: =IF(AND($AC$4<=$X11,$X11<$AD$4),AA11,0) -> 0 | AM11: =IF(AND($AC$5<=$X11,$X11<$AD$5),Y11,0) -> 0 | AN11: =IF(AND($AC$5<=$X11,$X11<$AD$5),Z11,0) -> 0 | AO11: =IF(AND($AC$5<=$X11,$X11<$AD$5),AA11,0) -> 0 | AP11: =IF(AND($AC$6<=$X11,$X11<$AD$6),Y11,0) -> 0 | AQ11: =IF(AND($AC$6<=$X11,$X11<$AD$6),Z11,0) -> 0 | AR11: =IF(AND($AC$6<=$X11,$X11<$AD$6),AA11,0) -> 0 | AS11: =IF(AND($AC$7<=$X11,$X11<$AD$7),Y11,0) -> 0 | AT11: =IF(AND($AC$7<=$X11,$X11<$AD$7),Z11,0) -> 0 | AU11: =IF(AND($AC$7<=$X11,$X11<$AD$7),AA11,0) -> 0 | AV11: =IF(AND($AC$8<=$X11,$X11<$AD$8),Y11,0) -> 0 | AW11: =IF(AND($AC$8<=$X11,$X11<$AD$8),Z11,0) -> 0 | AX11: =IF(AND($AC$8<=$X11,$X11<$AD$8),AA11,0) -> 0 | AY11: =IF(AND($AC$9<=$X11,$X11<$AD$9),Y11,0) -> 0 | AZ11: =IF(AND($AC$9<=$X11,$X11<$AD$9),Z11,0) -> 0 | BA11: =IF(AND($AC$9<=$X11,$X11<$AD$9),AA11,0) -> 0 | BB11: =IF(AND($AC$10<=$X11,$X11<$AD$10),Y11,0) -> 0 | BC11: =IF(AND($AC$10<=$X11,$X11<$AD$10),Z11,0) -> 0 | BD11: =IF(AND($AC$10<=$X11,$X11<$AD$10),AA11,0) -> 0 | BE11: =IF(AND($AC$11<=$X11,$X11<$AD$11),Y11,0) -> 0 | BF11: =IF(AND($AC$11<=$X11,$X11<$AD$11),Z11,0) -> 0 | BG11: =IF(AND($AC$11<=$X11,$X11<$AD$11),AA11,0) -> 0 | BH11: =IF(AND($AC$12<=$X11,$X11<$AD$12),Y11,0) -> 0 | BI11: =IF(AND($AC$12<=$X11,$X11<$AD$12),Z11,0) -> 0 | BJ11: =IF(AND($AC$12<=$X11,$X11<$AD$12),AA11,0) -> 0 | BK11: =IF(AND($AC$13<=$X11,$X11<$AD$13),Y11,0) -> 0 | BL11: =IF(AND($AC$13<=$X11,$X11<$AD$13),Z11,0) -> 0 | BM11: =IF(AND($AC$13<=$X11,$X11<$AD$13),AA11,0) -> 0 | BN11: =IF(AND($AC$14<=$X11,$X11<$AD$14),Y11,0) -> 0 | BO11: =IF(AND($AC$14<=$X11,$X11<$AD$14),Z11,0) -> 0 | BP11: =IF(AND($AC$14<=$X11,$X11<$AD$14),AA11,0) -> 0 | BQ11: =IF(AND($AC$15<=$X11,$X11<$AD$15),Y11,0) -> 0 | BR11: =IF(AND($AC$15<=$X11,$X11<$AD$15),Z11,0) -> 0 | BS11: =IF(AND($AC$15<=$X11,$X11<$AD$15),AA11,0) -> 0 | BT11: =IF(AND($AC$16<=$X11,$X11<$AD$16),Y11,0) -> 0 | BU11: =IF(AND($AC$16<=$X11,$X11<$AD$16),Z11,0) -> 0 | BV11: =IF(AND($AC$16<=$X11,$X11<$AD$16),AA11,0) -> 0 | BW11: =IF(AND($AC$17<=$X11,$X11<$AD$17),Y11,0) -> 0 | BX11: =IF(AND($AC$17<=$X11,$X11<$AD$17),Z11,0) -> 0 | BY11: =IF(AND($AC$17<=$X11,$X11<$AD$17),AA11,0) -> 0 | BZ11: =IF(AND($AC$18<=$X11,$X11<$AD$18),Y11,0) -> 0 | CA11: =IF(AND($AC$18<=$X11,$X11<$AD$18),Z11,0) -> 0 | CB11: =IF(AND($AC$18<=$X11,$X11<$AD$18),AA11,0) -> 0
B12: =IF('Summary Statistics'!$C$6=TRUE,Artists!$F11<B$3,Artists!$E11<B$3) -> FALSE | C12: =IF('Summary Statistics'!$C$6=TRUE,Artists!$F11<C$3,Artists!$E11<C$3) -> FALSE | D12: =IF('Summary Statistics'!$C$6=TRUE,Artists!$F11<D$3,Artists!$E11<D$3) -> FALSE | E12: =IF('Summary Statistics'!$C$6=TRUE,Artists!$F11<E$3,Artists!$E11<E$3) -> FALSE | F12: =IF('Summary Statistics'!$C$6=TRUE,Artists!$F11<F$3,Artists!$E11<F$3) -> FALSE | G12: =IF('Summary Statistics'!$C$6=TRUE,Artists!$F11<G$3,Artists!$E11<G$3) -> FALSE | H12: =IF('Summary Statistics'!$C$6=TRUE,Artists!$F11<H$3,Artists!$E11<H$3) -> FALSE | I12: =IF('Summary Statistics'!$C$6=TRUE,Artists!$F11<I$3,Artists!$E11<I$3) -> FALSE | ... K12: =IF('Summary Statistics'!$C$6=TRUE,Artists!$F11<K$3,Artists!$E11<K$3) -> FALSE | M12: =IF('Summary Statistics'!$C$7=TRUE,Albums!$F11<M$3,Albums!$E11<M$3) -> FALSE | N12: =IF('Summary Statistics'!$C$7=TRUE,Albums!$F11<N$3,Albums!$E11<N$3) -> FALSE | O12: =IF('Summary Statistics'!$C$7=TRUE,Albums!$F11<O$3,Albums!$E11<O$3) -> FALSE | P12: =IF('Summary Statistics'!$C$7=TRUE,Albums!$F11<P$3,Albums!$E11<P$3) -> FALSE | Q12: =IF('Summary Statistics'!$C$7=TRUE,Albums!$F11<Q$3,Albums!$E11<Q$3) -> FALSE | R12: =IF('Summary Statistics'!$C$7=TRUE,Albums!$F11<R$3,Albums!$E11<R$3) -> FALSE | S12: =IF('Summary Statistics'!$C$7=TRUE,Albums!$F11<S$3,Albums!$E11<S$3) -> FALSE | T12: =IF('Summary Statistics'!$C$7=TRUE,Albums!$F11<T$3,Albums!$E11<T$3) -> FALSE | ... V12: =IF('Summary Statistics'!$C$7=TRUE,Albums!$F11<V$3,Albums!$E11<V$3) -> FALSE | X12: =1+X11 -> 1909 | Y12: =COUNTIF('Cleaned Data'!$K$4:$K$5004,X12) -> 0 | Z12: =SUMIF('Cleaned Data'!$K$4:'Cleaned Data'!$K$5004,Calculations!X12,'Cleaned Data'!$J$4:$J$5004) -> 0 | AA12: =SUMIF('Cleaned Data'!$K$4:'Cleaned Data'!$K$5004,Calculations!X12,'Cleaned Data'!$H$4:$H$5004) -> 0 | AC12: 1980 | AD12: 1990 | AE12: 1980s | AF12: =SUM(BH3:BH153) -> 0 | AG12: =SUM(BI3:BI153) -> 0 | AH12: =SUM(BJ3:BJ153) -> 0 | AJ12: =IF(AND($AC$4<=$X12,$X12<$AD$4),Y12,0) -> 0 | AK12: =IF(AND($AC$4<=$X12,$X12<$AD$4),Z12,0) -> 0 | AL12: =IF(AND($AC$4<=$X12,$X12<$AD$4),AA12,0) -> 0 | AM12: =IF(AND($AC$5<=$X12,$X12<$AD$5),Y12,0) -> 0 | AN12: =IF(AND($AC$5<=$X12,$X12<$AD$5),Z12,0) -> 0 | AO12: =IF(AND($AC$5<=$X12,$X12<$AD$5),AA12,0) -> 0 | AP12: =IF(AND($AC$6<=$X12,$X12<$AD$6),Y12,0) -> 0 | AQ12: =IF(AND($AC$6<=$X12,$X12<$AD$6),Z12,0) -> 0 | AR12: =IF(AND($AC$6<=$X12,$X12<$AD$6),AA12,0) -> 0 | AS12: =IF(AND($AC$7<=$X12,$X12<$AD$7),Y12,0) -> 0 | AT12: =IF(AND($AC$7<=$X12,$X12<$AD$7),Z12,0) -> 0 | AU12: =IF(AND($AC$7<=$X12,$X12<$AD$7),AA12,0) -> 0 | AV12: =IF(AND($AC$8<=$X12,$X12<$AD$8),Y12,0) -> 0 | AW12: =IF(AND($AC$8<=$X12,$X12<$AD$8),Z12,0) -> 0 | AX12: =IF(AND($AC$8<=$X12,$X12<$AD$8),AA12,0) -> 0 | AY12: =IF(AND($AC$9<=$X12,$X12<$AD$9),Y12,0) -> 0 | AZ12: =IF(AND($AC$9<=$X12,$X12<$AD$9),Z12,0) -> 0 | BA12: =IF(AND($AC$9<=$X12,$X12<$AD$9),AA12,0) -> 0 | BB12: =IF(AND($AC$10<=$X12,$X12<$AD$10),Y12,0) -> 0 | BC12: =IF(AND($AC$10<=$X12,$X12<$AD$10),Z12,0) -> 0 | BD12: =IF(AND($AC$10<=$X12,$X12<$AD$10),AA12,0) -> 0 | BE12: =IF(AND($AC$11<=$X12,$X12<$AD$11),Y12,0) -> 0 | BF12: =IF(AND($AC$11<=$X12,$X12<$AD$11),Z12,0) -> 0 | BG12: =IF(AND($AC$11<=$X12,$X12<$AD$11),AA12,0) -> 0 | BH12: =IF(AND($AC$12<=$X12,$X12<$AD$12),Y12,0) -> 0 | BI12: =IF(AND($AC$12<=$X12,$X12<$AD$12),Z12,0) -> 0 | BJ12: =IF(AND($AC$12<=$X12,$X12<$AD$12),AA12,0) -> 0 | BK12: =IF(AND($AC$13<=$X12,$X12<$AD$13),Y12,0) -> 0 | BL12: =IF(AND($AC$13<=$X12,$X12<$AD$13),Z12,0) -> 0 | BM12: =IF(AND($AC$13<=$X12,$X12<$AD$13),AA12,0) -> 0 | BN12: =IF(AND($AC$14<=$X12,$X12<$AD$14),Y12,0) -> 0 | BO12: =IF(AND($AC$14<=$X12,$X12<$AD$14),Z12,0) -> 0 | BP12: =IF(AND($AC$14<=$X12,$X12<$AD$14),AA12,0) -> 0 | BQ12: =IF(AND($AC$15<=$X12,$X12<$AD$15),Y12,0) -> 0 | BR12: =IF(AND($AC$15<=$X12,$X12<$AD$15),Z12,0) -> 0 | BS12: =IF(AND($AC$15<=$X12,$X12<$AD$15),AA12,0) -> 0 | BT12: =IF(AND($AC$16<=$X12,$X12<$AD$16),Y12,0) -> 0 | BU12: =IF(AND($AC$16<=$X12,$X12<$AD$16),Z12,0) -> 0 | BV12: =IF(AND($AC$16<=$X12,$X12<$AD$16),AA12,0) -> 0 | BW12: =IF(AND($AC$17<=$X12,$X12<$AD$17),Y12,0) -> 0 | BX12: =IF(AND($AC$17<=$X12,$X12<$AD$17),Z12,0) -> 0 | BY12: =IF(AND($AC$17<=$X12,$X12<$AD$17),AA12,0) -> 0 | BZ12: =IF(AND($AC$18<=$X12,$X12<$AD$18),Y12,0) -> 0 | CA12: =IF(AND($AC$18<=$X12,$X12<$AD$18),Z12,0) -> 0 | CB12: =IF(AND($AC$18<=$X12,$X12<$AD$18),AA12,0) -> 0
